[2025-04-14T05:19:40.233+0000] {local_task_job_runner.py:123} INFO - ::group::Pre task execution logs
[2025-04-14T05:19:40.244+0000] {taskinstance.py:2614} INFO - Dependencies all met for dep_context=non-requeueable deps ti=<TaskInstance: data_ingestion_gcs_dag.fetch_permits_task manual__2025-04-14T05:14:22.544850+00:00 [queued]>
[2025-04-14T05:19:40.249+0000] {taskinstance.py:2614} INFO - Dependencies all met for dep_context=requeueable deps ti=<TaskInstance: data_ingestion_gcs_dag.fetch_permits_task manual__2025-04-14T05:14:22.544850+00:00 [queued]>
[2025-04-14T05:19:40.249+0000] {taskinstance.py:2867} INFO - Starting attempt 1 of 2
[2025-04-14T05:19:40.255+0000] {taskinstance.py:2890} INFO - Executing <Task(BranchPythonOperator): fetch_permits_task> on 2025-04-14 05:14:22.544850+00:00
[2025-04-14T05:19:40.259+0000] {warnings.py:112} WARNING - /home/***/.local/lib/python3.12/site-packages/***/task/task_runner/standard_task_runner.py:70: DeprecationWarning: This process (pid=180) is multi-threaded, use of fork() may lead to deadlocks in the child.
  pid = os.fork()

[2025-04-14T05:19:40.260+0000] {standard_task_runner.py:72} INFO - Started process 182 to run task
[2025-04-14T05:19:40.260+0000] {standard_task_runner.py:104} INFO - Running: ['***', 'tasks', 'run', 'data_ingestion_gcs_dag', 'fetch_permits_task', 'manual__2025-04-14T05:14:22.544850+00:00', '--job-id', '7', '--raw', '--subdir', 'DAGS_FOLDER/data_ingestion_gcs_dag.py', '--cfg-path', '/tmp/tmpi9d9lsuf']
[2025-04-14T05:19:40.261+0000] {standard_task_runner.py:105} INFO - Job 7: Subtask fetch_permits_task
[2025-04-14T05:19:40.284+0000] {task_command.py:467} INFO - Running <TaskInstance: data_ingestion_gcs_dag.fetch_permits_task manual__2025-04-14T05:14:22.544850+00:00 [running]> on host 958b532773e9
[2025-04-14T05:19:40.323+0000] {taskinstance.py:3134} INFO - Exporting env vars: AIRFLOW_CTX_DAG_OWNER='***' AIRFLOW_CTX_DAG_ID='data_ingestion_gcs_dag' AIRFLOW_CTX_TASK_ID='fetch_permits_task' AIRFLOW_CTX_EXECUTION_DATE='2025-04-14T05:14:22.544850+00:00' AIRFLOW_CTX_TRY_NUMBER='1' AIRFLOW_CTX_DAG_RUN_ID='manual__2025-04-14T05:14:22.544850+00:00'
[2025-04-14T05:19:40.324+0000] {logging_mixin.py:190} INFO - Task instance is in running state
[2025-04-14T05:19:40.324+0000] {logging_mixin.py:190} INFO -  Previous state of the Task instance: queued
[2025-04-14T05:19:40.324+0000] {logging_mixin.py:190} INFO - Current task name:fetch_permits_task state:running start_date:2025-04-14 05:19:40.244484+00:00
[2025-04-14T05:19:40.324+0000] {logging_mixin.py:190} INFO - Dag name:data_ingestion_gcs_dag and current dag run status:running
[2025-04-14T05:19:40.325+0000] {taskinstance.py:732} INFO - ::endgroup::
[2025-04-14T05:19:40.325+0000] {baseoperator.py:423} WARNING - BranchPythonOperator.execute cannot be called outside TaskInstance!
[2025-04-14T05:19:40.330+0000] {logging_mixin.py:190} INFO - Fetching records for 2020-04-29 (offset=0)
[2025-04-14T05:19:40.971+0000] {taskinstance.py:3313} ERROR - Task failed with exception
Traceback (most recent call last):
  File "/home/airflow/.local/lib/python3.12/site-packages/airflow/models/taskinstance.py", line 768, in _execute_task
    result = _execute_callable(context=context, **execute_callable_kwargs)
             ^^^^^^^^^^^^^^^^^^^^^^^^^^^^^^^^^^^^^^^^^^^^^^^^^^^^^^^^^^^^^
  File "/home/airflow/.local/lib/python3.12/site-packages/airflow/models/taskinstance.py", line 734, in _execute_callable
    return ExecutionCallableRunner(
           ^^^^^^^^^^^^^^^^^^^^^^^^
  File "/home/airflow/.local/lib/python3.12/site-packages/airflow/utils/operator_helpers.py", line 252, in run
    return self.func(*args, **kwargs)
           ^^^^^^^^^^^^^^^^^^^^^^^^^^
  File "/home/airflow/.local/lib/python3.12/site-packages/airflow/models/baseoperator.py", line 424, in wrapper
    return func(self, *args, **kwargs)
           ^^^^^^^^^^^^^^^^^^^^^^^^^^^
  File "/home/airflow/.local/lib/python3.12/site-packages/airflow/operators/python.py", line 274, in execute
    return self.do_branch(context, super().execute(context))
                                   ^^^^^^^^^^^^^^^^^^^^^^^^
  File "/home/airflow/.local/lib/python3.12/site-packages/airflow/models/baseoperator.py", line 424, in wrapper
    return func(self, *args, **kwargs)
           ^^^^^^^^^^^^^^^^^^^^^^^^^^^
  File "/home/airflow/.local/lib/python3.12/site-packages/airflow/operators/python.py", line 238, in execute
    return_value = self.execute_callable()
                   ^^^^^^^^^^^^^^^^^^^^^^^
  File "/home/airflow/.local/lib/python3.12/site-packages/airflow/operators/python.py", line 256, in execute_callable
    return runner.run(*self.op_args, **self.op_kwargs)
           ^^^^^^^^^^^^^^^^^^^^^^^^^^^^^^^^^^^^^^^^^^^
  File "/home/airflow/.local/lib/python3.12/site-packages/airflow/utils/operator_helpers.py", line 252, in run
    return self.func(*args, **kwargs)
           ^^^^^^^^^^^^^^^^^^^^^^^^^^
  File "/opt/airflow/dags/data_ingestion_gcs_dag.py", line 86, in fetch_permits
    results = client.get(
              ^^^^^^^^^^^
  File "/home/airflow/.local/lib/python3.12/site-packages/sodapy/socrata.py", line 412, in get
    response = self._perform_request(
               ^^^^^^^^^^^^^^^^^^^^^^
  File "/home/airflow/.local/lib/python3.12/site-packages/sodapy/socrata.py", line 555, in _perform_request
    utils.raise_for_status(response)
  File "/home/airflow/.local/lib/python3.12/site-packages/sodapy/utils.py", line 30, in raise_for_status
    raise requests.exceptions.HTTPError(http_error_msg, response=response)
requests.exceptions.HTTPError: 400 Client Error: Bad Request.
	Unrecognized arguments [timeout]
[2025-04-14T05:19:40.983+0000] {logging_mixin.py:190} INFO - Task instance in failure state
[2025-04-14T05:19:40.983+0000] {logging_mixin.py:190} INFO - Task start:2025-04-14 05:19:40.244484+00:00 end:2025-04-14 05:19:40.983044+00:00 duration:0.73856
[2025-04-14T05:19:40.984+0000] {logging_mixin.py:190} INFO - Task:<Task(BranchPythonOperator): fetch_permits_task> dag:<DAG: data_ingestion_gcs_dag> dagrun:<DagRun data_ingestion_gcs_dag @ 2025-04-14 05:14:22.544850+00:00: manual__2025-04-14T05:14:22.544850+00:00, state:running, queued_at: 2025-04-14 05:14:22.560955+00:00. externally triggered: True>
[2025-04-14T05:19:40.984+0000] {logging_mixin.py:190} INFO - Failure caused by 400 Client Error: Bad Request.
	Unrecognized arguments [timeout]
[2025-04-14T05:19:40.984+0000] {taskinstance.py:1226} INFO - Marking task as UP_FOR_RETRY. dag_id=data_ingestion_gcs_dag, task_id=fetch_permits_task, run_id=manual__2025-04-14T05:14:22.544850+00:00, execution_date=20250414T051422, start_date=20250414T051940, end_date=20250414T051940
[2025-04-14T05:19:41.006+0000] {taskinstance.py:341} INFO - ::group::Post task execution logs
[2025-04-14T05:19:41.006+0000] {standard_task_runner.py:124} ERROR - Failed to execute job 7 for task fetch_permits_task (400 Client Error: Bad Request.
	Unrecognized arguments [timeout]; 182)
Traceback (most recent call last):
  File "/home/airflow/.local/lib/python3.12/site-packages/airflow/task/task_runner/standard_task_runner.py", line 117, in _start_by_fork
    ret = args.func(args, dag=self.dag)
          ^^^^^^^^^^^^^^^^^^^^^^^^^^^^^
  File "/home/airflow/.local/lib/python3.12/site-packages/airflow/cli/cli_config.py", line 49, in command
    return func(*args, **kwargs)
           ^^^^^^^^^^^^^^^^^^^^^
  File "/home/airflow/.local/lib/python3.12/site-packages/airflow/utils/cli.py", line 116, in wrapper
    return f(*args, **kwargs)
           ^^^^^^^^^^^^^^^^^^
  File "/home/airflow/.local/lib/python3.12/site-packages/airflow/cli/commands/task_command.py", line 483, in task_run
    task_return_code = _run_task_by_selected_method(args, _dag, ti)
                       ^^^^^^^^^^^^^^^^^^^^^^^^^^^^^^^^^^^^^^^^^^^^
  File "/home/airflow/.local/lib/python3.12/site-packages/airflow/cli/commands/task_command.py", line 256, in _run_task_by_selected_method
    return _run_raw_task(args, ti)
           ^^^^^^^^^^^^^^^^^^^^^^^
  File "/home/airflow/.local/lib/python3.12/site-packages/airflow/cli/commands/task_command.py", line 341, in _run_raw_task
    return ti._run_raw_task(
           ^^^^^^^^^^^^^^^^^
  File "/home/airflow/.local/lib/python3.12/site-packages/airflow/utils/session.py", line 97, in wrapper
    return func(*args, session=session, **kwargs)
           ^^^^^^^^^^^^^^^^^^^^^^^^^^^^^^^^^^^^^^
  File "/home/airflow/.local/lib/python3.12/site-packages/airflow/models/taskinstance.py", line 3006, in _run_raw_task
    return _run_raw_task(
           ^^^^^^^^^^^^^^
  File "/home/airflow/.local/lib/python3.12/site-packages/airflow/models/taskinstance.py", line 274, in _run_raw_task
    TaskInstance._execute_task_with_callbacks(
  File "/home/airflow/.local/lib/python3.12/site-packages/airflow/models/taskinstance.py", line 3161, in _execute_task_with_callbacks
    result = self._execute_task(context, task_orig)
             ^^^^^^^^^^^^^^^^^^^^^^^^^^^^^^^^^^^^^^
  File "/home/airflow/.local/lib/python3.12/site-packages/airflow/models/taskinstance.py", line 3185, in _execute_task
    return _execute_task(self, context, task_orig)
           ^^^^^^^^^^^^^^^^^^^^^^^^^^^^^^^^^^^^^^^
  File "/home/airflow/.local/lib/python3.12/site-packages/airflow/models/taskinstance.py", line 768, in _execute_task
    result = _execute_callable(context=context, **execute_callable_kwargs)
             ^^^^^^^^^^^^^^^^^^^^^^^^^^^^^^^^^^^^^^^^^^^^^^^^^^^^^^^^^^^^^
  File "/home/airflow/.local/lib/python3.12/site-packages/airflow/models/taskinstance.py", line 734, in _execute_callable
    return ExecutionCallableRunner(
           ^^^^^^^^^^^^^^^^^^^^^^^^
  File "/home/airflow/.local/lib/python3.12/site-packages/airflow/utils/operator_helpers.py", line 252, in run
    return self.func(*args, **kwargs)
           ^^^^^^^^^^^^^^^^^^^^^^^^^^
  File "/home/airflow/.local/lib/python3.12/site-packages/airflow/models/baseoperator.py", line 424, in wrapper
    return func(self, *args, **kwargs)
           ^^^^^^^^^^^^^^^^^^^^^^^^^^^
  File "/home/airflow/.local/lib/python3.12/site-packages/airflow/operators/python.py", line 274, in execute
    return self.do_branch(context, super().execute(context))
                                   ^^^^^^^^^^^^^^^^^^^^^^^^
  File "/home/airflow/.local/lib/python3.12/site-packages/airflow/models/baseoperator.py", line 424, in wrapper
    return func(self, *args, **kwargs)
           ^^^^^^^^^^^^^^^^^^^^^^^^^^^
  File "/home/airflow/.local/lib/python3.12/site-packages/airflow/operators/python.py", line 238, in execute
    return_value = self.execute_callable()
                   ^^^^^^^^^^^^^^^^^^^^^^^
  File "/home/airflow/.local/lib/python3.12/site-packages/airflow/operators/python.py", line 256, in execute_callable
    return runner.run(*self.op_args, **self.op_kwargs)
           ^^^^^^^^^^^^^^^^^^^^^^^^^^^^^^^^^^^^^^^^^^^
  File "/home/airflow/.local/lib/python3.12/site-packages/airflow/utils/operator_helpers.py", line 252, in run
    return self.func(*args, **kwargs)
           ^^^^^^^^^^^^^^^^^^^^^^^^^^
  File "/opt/airflow/dags/data_ingestion_gcs_dag.py", line 86, in fetch_permits
    results = client.get(
              ^^^^^^^^^^^
  File "/home/airflow/.local/lib/python3.12/site-packages/sodapy/socrata.py", line 412, in get
    response = self._perform_request(
               ^^^^^^^^^^^^^^^^^^^^^^
  File "/home/airflow/.local/lib/python3.12/site-packages/sodapy/socrata.py", line 555, in _perform_request
    utils.raise_for_status(response)
  File "/home/airflow/.local/lib/python3.12/site-packages/sodapy/utils.py", line 30, in raise_for_status
    raise requests.exceptions.HTTPError(http_error_msg, response=response)
requests.exceptions.HTTPError: 400 Client Error: Bad Request.
	Unrecognized arguments [timeout]
[2025-04-14T05:19:41.018+0000] {local_task_job_runner.py:266} INFO - Task exited with return code 1
[2025-04-14T05:19:41.031+0000] {taskinstance.py:3901} INFO - 0 downstream tasks scheduled from follow-on schedule check
[2025-04-14T05:19:41.032+0000] {local_task_job_runner.py:245} INFO - ::endgroup::
