[2025-04-13T23:17:57.335+0000] {local_task_job_runner.py:123} INFO - ::group::Pre task execution logs
[2025-04-13T23:17:57.345+0000] {taskinstance.py:2614} INFO - Dependencies all met for dep_context=non-requeueable deps ti=<TaskInstance: data_ingestion_gcs_dag.get_last_issued_date_task manual__2025-04-13T23:07:35.712423+00:00 [queued]>
[2025-04-13T23:17:57.349+0000] {taskinstance.py:2614} INFO - Dependencies all met for dep_context=requeueable deps ti=<TaskInstance: data_ingestion_gcs_dag.get_last_issued_date_task manual__2025-04-13T23:07:35.712423+00:00 [queued]>
[2025-04-13T23:17:57.349+0000] {taskinstance.py:2867} INFO - Starting attempt 2 of 2
[2025-04-13T23:17:57.355+0000] {taskinstance.py:2890} INFO - Executing <Task(PythonOperator): get_last_issued_date_task> on 2025-04-13 23:07:35.712423+00:00
[2025-04-13T23:17:57.359+0000] {warnings.py:112} WARNING - /home/***/.local/lib/python3.12/site-packages/***/task/task_runner/standard_task_runner.py:70: DeprecationWarning: This process (pid=242) is multi-threaded, use of fork() may lead to deadlocks in the child.
  pid = os.fork()

[2025-04-13T23:17:57.360+0000] {standard_task_runner.py:72} INFO - Started process 244 to run task
[2025-04-13T23:17:57.361+0000] {standard_task_runner.py:104} INFO - Running: ['***', 'tasks', 'run', 'data_ingestion_gcs_dag', 'get_last_issued_date_task', 'manual__2025-04-13T23:07:35.712423+00:00', '--job-id', '9', '--raw', '--subdir', 'DAGS_FOLDER/data_ingestion_gcs_dag.py', '--cfg-path', '/tmp/tmpbql_fuh5']
[2025-04-13T23:17:57.361+0000] {standard_task_runner.py:105} INFO - Job 9: Subtask get_last_issued_date_task
[2025-04-13T23:17:57.396+0000] {task_command.py:467} INFO - Running <TaskInstance: data_ingestion_gcs_dag.get_last_issued_date_task manual__2025-04-13T23:07:35.712423+00:00 [running]> on host 3aaac60a2eb2
[2025-04-13T23:17:57.450+0000] {taskinstance.py:3134} INFO - Exporting env vars: AIRFLOW_CTX_DAG_OWNER='***' AIRFLOW_CTX_DAG_ID='data_ingestion_gcs_dag' AIRFLOW_CTX_TASK_ID='get_last_issued_date_task' AIRFLOW_CTX_EXECUTION_DATE='2025-04-13T23:07:35.712423+00:00' AIRFLOW_CTX_TRY_NUMBER='2' AIRFLOW_CTX_DAG_RUN_ID='manual__2025-04-13T23:07:35.712423+00:00'
[2025-04-13T23:17:57.451+0000] {logging_mixin.py:190} INFO - Task instance is in running state
[2025-04-13T23:17:57.451+0000] {logging_mixin.py:190} INFO -  Previous state of the Task instance: queued
[2025-04-13T23:17:57.451+0000] {logging_mixin.py:190} INFO - Current task name:get_last_issued_date_task state:running start_date:2025-04-13 23:17:57.345889+00:00
[2025-04-13T23:17:57.451+0000] {logging_mixin.py:190} INFO - Dag name:data_ingestion_gcs_dag and current dag run status:running
[2025-04-13T23:17:57.451+0000] {taskinstance.py:732} INFO - ::endgroup::
[2025-04-13T23:17:58.383+0000] {taskinstance.py:3313} ERROR - Task failed with exception
Traceback (most recent call last):
  File "/home/airflow/.local/lib/python3.12/site-packages/airflow/models/taskinstance.py", line 768, in _execute_task
    result = _execute_callable(context=context, **execute_callable_kwargs)
             ^^^^^^^^^^^^^^^^^^^^^^^^^^^^^^^^^^^^^^^^^^^^^^^^^^^^^^^^^^^^^
  File "/home/airflow/.local/lib/python3.12/site-packages/airflow/models/taskinstance.py", line 734, in _execute_callable
    return ExecutionCallableRunner(
           ^^^^^^^^^^^^^^^^^^^^^^^^
  File "/home/airflow/.local/lib/python3.12/site-packages/airflow/utils/operator_helpers.py", line 252, in run
    return self.func(*args, **kwargs)
           ^^^^^^^^^^^^^^^^^^^^^^^^^^
  File "/home/airflow/.local/lib/python3.12/site-packages/airflow/models/baseoperator.py", line 424, in wrapper
    return func(self, *args, **kwargs)
           ^^^^^^^^^^^^^^^^^^^^^^^^^^^
  File "/home/airflow/.local/lib/python3.12/site-packages/airflow/operators/python.py", line 238, in execute
    return_value = self.execute_callable()
                   ^^^^^^^^^^^^^^^^^^^^^^^
  File "/home/airflow/.local/lib/python3.12/site-packages/airflow/operators/python.py", line 256, in execute_callable
    return runner.run(*self.op_args, **self.op_kwargs)
           ^^^^^^^^^^^^^^^^^^^^^^^^^^^^^^^^^^^^^^^^^^^
  File "/home/airflow/.local/lib/python3.12/site-packages/airflow/utils/operator_helpers.py", line 252, in run
    return self.func(*args, **kwargs)
           ^^^^^^^^^^^^^^^^^^^^^^^^^^
  File "/opt/airflow/dags/data_ingestion_gcs_dag.py", line 53, in get_last_issued_date
    rows = query_job.result()  # Waits for query to finish
           ^^^^^^^^^^^^^^^^^^
  File "/home/airflow/.local/lib/python3.12/site-packages/google/cloud/bigquery/job/query.py", line 1590, in result
    do_get_result()
  File "/home/airflow/.local/lib/python3.12/site-packages/google/api_core/retry/retry_unary.py", line 293, in retry_wrapped_func
    return retry_target(
           ^^^^^^^^^^^^^
  File "/home/airflow/.local/lib/python3.12/site-packages/google/api_core/retry/retry_unary.py", line 153, in retry_target
    _retry_error_helper(
  File "/home/airflow/.local/lib/python3.12/site-packages/google/api_core/retry/retry_base.py", line 212, in _retry_error_helper
    raise final_exc from source_exc
  File "/home/airflow/.local/lib/python3.12/site-packages/google/api_core/retry/retry_unary.py", line 144, in retry_target
    result = target()
             ^^^^^^^^
  File "/home/airflow/.local/lib/python3.12/site-packages/google/cloud/bigquery/job/query.py", line 1579, in do_get_result
    super(QueryJob, self).result(retry=retry, timeout=timeout)
  File "/home/airflow/.local/lib/python3.12/site-packages/google/cloud/bigquery/job/base.py", line 971, in result
    return super(_AsyncJob, self).result(timeout=timeout, **kwargs)
           ^^^^^^^^^^^^^^^^^^^^^^^^^^^^^^^^^^^^^^^^^^^^^^^^^^^^^^^^
  File "/home/airflow/.local/lib/python3.12/site-packages/google/api_core/future/polling.py", line 261, in result
    raise self._exception
google.api_core.exceptions.BadRequest: 400 Error while reading table: nyc-projects-455321.building_permits.external_table, error message: Failed to expand table nyc-projects-455321.building_permits.external_table with file pattern gs://nyc-projects-455321-bucket/raw/building_permits.parquet: matched no files. File: gs://nyc-projects-455321-bucket/raw/building_permits.parquet; reason: invalid, location: gs://nyc-projects-455321-bucket/raw/building_permits.parquet, message: Error while reading table: nyc-projects-455321.building_permits.external_table, error message: Failed to expand table nyc-projects-455321.building_permits.external_table with file pattern gs://nyc-projects-455321-bucket/raw/building_permits.parquet: matched no files. File: gs://nyc-projects-455321-bucket/raw/building_permits.parquet

Location: US
Job ID: 6178487c-b1b0-4d63-a291-15007f83642f

[2025-04-13T23:17:58.411+0000] {logging_mixin.py:190} INFO - Task instance in failure state
[2025-04-13T23:17:58.412+0000] {logging_mixin.py:190} INFO - Task start:2025-04-13 23:17:57.345889+00:00 end:2025-04-13 23:17:58.410433+00:00 duration:1.064544
[2025-04-13T23:17:58.413+0000] {logging_mixin.py:190} INFO - Task:<Task(PythonOperator): get_last_issued_date_task> dag:<DAG: data_ingestion_gcs_dag> dagrun:<DagRun data_ingestion_gcs_dag @ 2025-04-13 23:07:35.712423+00:00: manual__2025-04-13T23:07:35.712423+00:00, state:running, queued_at: 2025-04-13 23:07:35.727766+00:00. externally triggered: True>
[2025-04-13T23:17:58.414+0000] {logging_mixin.py:190} INFO - Failure caused by 400 Error while reading table: nyc-projects-455321.building_permits.external_table, error message: Failed to expand table nyc-projects-455321.building_permits.external_table with file pattern gs://nyc-projects-455321-bucket/raw/building_permits.parquet: matched no files. File: gs://nyc-projects-455321-bucket/raw/building_permits.parquet; reason: invalid, location: gs://nyc-projects-455321-bucket/raw/building_permits.parquet, message: Error while reading table: nyc-projects-455321.building_permits.external_table, error message: Failed to expand table nyc-projects-455321.building_permits.external_table with file pattern gs://nyc-projects-455321-bucket/raw/building_permits.parquet: matched no files. File: gs://nyc-projects-455321-bucket/raw/building_permits.parquet

Location: US
Job ID: 6178487c-b1b0-4d63-a291-15007f83642f
[2025-04-13T23:17:58.415+0000] {taskinstance.py:1226} INFO - Marking task as FAILED. dag_id=data_ingestion_gcs_dag, task_id=get_last_issued_date_task, run_id=manual__2025-04-13T23:07:35.712423+00:00, execution_date=20250413T230735, start_date=20250413T231757, end_date=20250413T231758
[2025-04-13T23:17:58.463+0000] {taskinstance.py:341} INFO - ::group::Post task execution logs
[2025-04-13T23:17:58.465+0000] {standard_task_runner.py:124} ERROR - Failed to execute job 9 for task get_last_issued_date_task (400 Error while reading table: nyc-projects-455321.building_permits.external_table, error message: Failed to expand table nyc-projects-455321.building_permits.external_table with file pattern gs://nyc-projects-455321-bucket/raw/building_permits.parquet: matched no files. File: gs://nyc-projects-455321-bucket/raw/building_permits.parquet; reason: invalid, location: gs://nyc-projects-455321-bucket/raw/building_permits.parquet, message: Error while reading table: nyc-projects-455321.building_permits.external_table, error message: Failed to expand table nyc-projects-455321.building_permits.external_table with file pattern gs://nyc-projects-455321-bucket/raw/building_permits.parquet: matched no files. File: gs://nyc-projects-455321-bucket/raw/building_permits.parquet

Location: US
Job ID: 6178487c-b1b0-4d63-a291-15007f83642f
; 244)
Traceback (most recent call last):
  File "/home/airflow/.local/lib/python3.12/site-packages/airflow/task/task_runner/standard_task_runner.py", line 117, in _start_by_fork
    ret = args.func(args, dag=self.dag)
          ^^^^^^^^^^^^^^^^^^^^^^^^^^^^^
  File "/home/airflow/.local/lib/python3.12/site-packages/airflow/cli/cli_config.py", line 49, in command
    return func(*args, **kwargs)
           ^^^^^^^^^^^^^^^^^^^^^
  File "/home/airflow/.local/lib/python3.12/site-packages/airflow/utils/cli.py", line 116, in wrapper
    return f(*args, **kwargs)
           ^^^^^^^^^^^^^^^^^^
  File "/home/airflow/.local/lib/python3.12/site-packages/airflow/cli/commands/task_command.py", line 483, in task_run
    task_return_code = _run_task_by_selected_method(args, _dag, ti)
                       ^^^^^^^^^^^^^^^^^^^^^^^^^^^^^^^^^^^^^^^^^^^^
  File "/home/airflow/.local/lib/python3.12/site-packages/airflow/cli/commands/task_command.py", line 256, in _run_task_by_selected_method
    return _run_raw_task(args, ti)
           ^^^^^^^^^^^^^^^^^^^^^^^
  File "/home/airflow/.local/lib/python3.12/site-packages/airflow/cli/commands/task_command.py", line 341, in _run_raw_task
    return ti._run_raw_task(
           ^^^^^^^^^^^^^^^^^
  File "/home/airflow/.local/lib/python3.12/site-packages/airflow/utils/session.py", line 97, in wrapper
    return func(*args, session=session, **kwargs)
           ^^^^^^^^^^^^^^^^^^^^^^^^^^^^^^^^^^^^^^
  File "/home/airflow/.local/lib/python3.12/site-packages/airflow/models/taskinstance.py", line 3006, in _run_raw_task
    return _run_raw_task(
           ^^^^^^^^^^^^^^
  File "/home/airflow/.local/lib/python3.12/site-packages/airflow/models/taskinstance.py", line 274, in _run_raw_task
    TaskInstance._execute_task_with_callbacks(
  File "/home/airflow/.local/lib/python3.12/site-packages/airflow/models/taskinstance.py", line 3161, in _execute_task_with_callbacks
    result = self._execute_task(context, task_orig)
             ^^^^^^^^^^^^^^^^^^^^^^^^^^^^^^^^^^^^^^
  File "/home/airflow/.local/lib/python3.12/site-packages/airflow/models/taskinstance.py", line 3185, in _execute_task
    return _execute_task(self, context, task_orig)
           ^^^^^^^^^^^^^^^^^^^^^^^^^^^^^^^^^^^^^^^
  File "/home/airflow/.local/lib/python3.12/site-packages/airflow/models/taskinstance.py", line 768, in _execute_task
    result = _execute_callable(context=context, **execute_callable_kwargs)
             ^^^^^^^^^^^^^^^^^^^^^^^^^^^^^^^^^^^^^^^^^^^^^^^^^^^^^^^^^^^^^
  File "/home/airflow/.local/lib/python3.12/site-packages/airflow/models/taskinstance.py", line 734, in _execute_callable
    return ExecutionCallableRunner(
           ^^^^^^^^^^^^^^^^^^^^^^^^
  File "/home/airflow/.local/lib/python3.12/site-packages/airflow/utils/operator_helpers.py", line 252, in run
    return self.func(*args, **kwargs)
           ^^^^^^^^^^^^^^^^^^^^^^^^^^
  File "/home/airflow/.local/lib/python3.12/site-packages/airflow/models/baseoperator.py", line 424, in wrapper
    return func(self, *args, **kwargs)
           ^^^^^^^^^^^^^^^^^^^^^^^^^^^
  File "/home/airflow/.local/lib/python3.12/site-packages/airflow/operators/python.py", line 238, in execute
    return_value = self.execute_callable()
                   ^^^^^^^^^^^^^^^^^^^^^^^
  File "/home/airflow/.local/lib/python3.12/site-packages/airflow/operators/python.py", line 256, in execute_callable
    return runner.run(*self.op_args, **self.op_kwargs)
           ^^^^^^^^^^^^^^^^^^^^^^^^^^^^^^^^^^^^^^^^^^^
  File "/home/airflow/.local/lib/python3.12/site-packages/airflow/utils/operator_helpers.py", line 252, in run
    return self.func(*args, **kwargs)
           ^^^^^^^^^^^^^^^^^^^^^^^^^^
  File "/opt/airflow/dags/data_ingestion_gcs_dag.py", line 53, in get_last_issued_date
    rows = query_job.result()  # Waits for query to finish
           ^^^^^^^^^^^^^^^^^^
  File "/home/airflow/.local/lib/python3.12/site-packages/google/cloud/bigquery/job/query.py", line 1590, in result
    do_get_result()
  File "/home/airflow/.local/lib/python3.12/site-packages/google/api_core/retry/retry_unary.py", line 293, in retry_wrapped_func
    return retry_target(
           ^^^^^^^^^^^^^
  File "/home/airflow/.local/lib/python3.12/site-packages/google/api_core/retry/retry_unary.py", line 153, in retry_target
    _retry_error_helper(
  File "/home/airflow/.local/lib/python3.12/site-packages/google/api_core/retry/retry_base.py", line 212, in _retry_error_helper
    raise final_exc from source_exc
  File "/home/airflow/.local/lib/python3.12/site-packages/google/api_core/retry/retry_unary.py", line 144, in retry_target
    result = target()
             ^^^^^^^^
  File "/home/airflow/.local/lib/python3.12/site-packages/google/cloud/bigquery/job/query.py", line 1579, in do_get_result
    super(QueryJob, self).result(retry=retry, timeout=timeout)
  File "/home/airflow/.local/lib/python3.12/site-packages/google/cloud/bigquery/job/base.py", line 971, in result
    return super(_AsyncJob, self).result(timeout=timeout, **kwargs)
           ^^^^^^^^^^^^^^^^^^^^^^^^^^^^^^^^^^^^^^^^^^^^^^^^^^^^^^^^
  File "/home/airflow/.local/lib/python3.12/site-packages/google/api_core/future/polling.py", line 261, in result
    raise self._exception
google.api_core.exceptions.BadRequest: 400 Error while reading table: nyc-projects-455321.building_permits.external_table, error message: Failed to expand table nyc-projects-455321.building_permits.external_table with file pattern gs://nyc-projects-455321-bucket/raw/building_permits.parquet: matched no files. File: gs://nyc-projects-455321-bucket/raw/building_permits.parquet; reason: invalid, location: gs://nyc-projects-455321-bucket/raw/building_permits.parquet, message: Error while reading table: nyc-projects-455321.building_permits.external_table, error message: Failed to expand table nyc-projects-455321.building_permits.external_table with file pattern gs://nyc-projects-455321-bucket/raw/building_permits.parquet: matched no files. File: gs://nyc-projects-455321-bucket/raw/building_permits.parquet

Location: US
Job ID: 6178487c-b1b0-4d63-a291-15007f83642f

[2025-04-13T23:17:58.487+0000] {local_task_job_runner.py:266} INFO - Task exited with return code 1
[2025-04-13T23:17:58.522+0000] {taskinstance.py:3901} INFO - 0 downstream tasks scheduled from follow-on schedule check
[2025-04-13T23:17:58.524+0000] {local_task_job_runner.py:245} INFO - ::endgroup::
