[2025-04-17T01:07:49.950+0000] {local_task_job_runner.py:123} INFO - ::group::Pre task execution logs
[2025-04-17T01:07:49.961+0000] {taskinstance.py:2614} INFO - Dependencies all met for dep_context=non-requeueable deps ti=<TaskInstance: data_ingestion_gcs_dag.fetch_permits_task scheduled__2025-04-16T00:00:00+00:00 [queued]>
[2025-04-17T01:07:49.966+0000] {taskinstance.py:2614} INFO - Dependencies all met for dep_context=requeueable deps ti=<TaskInstance: data_ingestion_gcs_dag.fetch_permits_task scheduled__2025-04-16T00:00:00+00:00 [queued]>
[2025-04-17T01:07:49.966+0000] {taskinstance.py:2867} INFO - Starting attempt 2 of 2
[2025-04-17T01:07:49.972+0000] {taskinstance.py:2890} INFO - Executing <Task(BranchPythonOperator): fetch_permits_task> on 2025-04-16 00:00:00+00:00
[2025-04-17T01:07:49.976+0000] {warnings.py:112} WARNING - /home/***/.local/lib/python3.12/site-packages/***/task/task_runner/standard_task_runner.py:70: DeprecationWarning: This process (pid=164) is multi-threaded, use of fork() may lead to deadlocks in the child.
  pid = os.fork()

[2025-04-17T01:07:49.977+0000] {standard_task_runner.py:72} INFO - Started process 166 to run task
[2025-04-17T01:07:49.977+0000] {standard_task_runner.py:104} INFO - Running: ['***', 'tasks', 'run', 'data_ingestion_gcs_dag', 'fetch_permits_task', 'scheduled__2025-04-16T00:00:00+00:00', '--job-id', '5', '--raw', '--subdir', 'DAGS_FOLDER/data_ingestion_gcs_dag.py', '--cfg-path', '/tmp/tmpywdybc_o']
[2025-04-17T01:07:49.978+0000] {standard_task_runner.py:105} INFO - Job 5: Subtask fetch_permits_task
[2025-04-17T01:07:50.004+0000] {task_command.py:467} INFO - Running <TaskInstance: data_ingestion_gcs_dag.fetch_permits_task scheduled__2025-04-16T00:00:00+00:00 [running]> on host a5d139dec566
[2025-04-17T01:07:50.042+0000] {taskinstance.py:3134} INFO - Exporting env vars: AIRFLOW_CTX_DAG_OWNER='***' AIRFLOW_CTX_DAG_ID='data_ingestion_gcs_dag' AIRFLOW_CTX_TASK_ID='fetch_permits_task' AIRFLOW_CTX_EXECUTION_DATE='2025-04-16T00:00:00+00:00' AIRFLOW_CTX_TRY_NUMBER='2' AIRFLOW_CTX_DAG_RUN_ID='scheduled__2025-04-16T00:00:00+00:00'
[2025-04-17T01:07:50.043+0000] {logging_mixin.py:190} INFO - Task instance is in running state
[2025-04-17T01:07:50.044+0000] {logging_mixin.py:190} INFO -  Previous state of the Task instance: queued
[2025-04-17T01:07:50.044+0000] {logging_mixin.py:190} INFO - Current task name:fetch_permits_task state:running start_date:2025-04-17 01:07:49.961841+00:00
[2025-04-17T01:07:50.044+0000] {logging_mixin.py:190} INFO - Dag name:data_ingestion_gcs_dag and current dag run status:running
[2025-04-17T01:07:50.044+0000] {taskinstance.py:732} INFO - ::endgroup::
[2025-04-17T01:07:50.044+0000] {baseoperator.py:423} WARNING - BranchPythonOperator.execute cannot be called outside TaskInstance!
[2025-04-17T01:07:50.045+0000] {taskinstance.py:3313} ERROR - Task failed with exception
Traceback (most recent call last):
  File "/home/airflow/.local/lib/python3.12/site-packages/airflow/models/taskinstance.py", line 768, in _execute_task
    result = _execute_callable(context=context, **execute_callable_kwargs)
             ^^^^^^^^^^^^^^^^^^^^^^^^^^^^^^^^^^^^^^^^^^^^^^^^^^^^^^^^^^^^^
  File "/home/airflow/.local/lib/python3.12/site-packages/airflow/models/taskinstance.py", line 734, in _execute_callable
    return ExecutionCallableRunner(
           ^^^^^^^^^^^^^^^^^^^^^^^^
  File "/home/airflow/.local/lib/python3.12/site-packages/airflow/utils/operator_helpers.py", line 252, in run
    return self.func(*args, **kwargs)
           ^^^^^^^^^^^^^^^^^^^^^^^^^^
  File "/home/airflow/.local/lib/python3.12/site-packages/airflow/models/baseoperator.py", line 424, in wrapper
    return func(self, *args, **kwargs)
           ^^^^^^^^^^^^^^^^^^^^^^^^^^^
  File "/home/airflow/.local/lib/python3.12/site-packages/airflow/operators/python.py", line 274, in execute
    return self.do_branch(context, super().execute(context))
                                   ^^^^^^^^^^^^^^^^^^^^^^^^
  File "/home/airflow/.local/lib/python3.12/site-packages/airflow/models/baseoperator.py", line 424, in wrapper
    return func(self, *args, **kwargs)
           ^^^^^^^^^^^^^^^^^^^^^^^^^^^
  File "/home/airflow/.local/lib/python3.12/site-packages/airflow/operators/python.py", line 238, in execute
    return_value = self.execute_callable()
                   ^^^^^^^^^^^^^^^^^^^^^^^
  File "/home/airflow/.local/lib/python3.12/site-packages/airflow/operators/python.py", line 256, in execute_callable
    return runner.run(*self.op_args, **self.op_kwargs)
           ^^^^^^^^^^^^^^^^^^^^^^^^^^^^^^^^^^^^^^^^^^^
  File "/home/airflow/.local/lib/python3.12/site-packages/airflow/utils/operator_helpers.py", line 252, in run
    return self.func(*args, **kwargs)
           ^^^^^^^^^^^^^^^^^^^^^^^^^^
  File "/opt/airflow/dags/data_ingestion_gcs_dag.py", line 70, in fetch_permits
    with open(token_file_path, "r") as file:
         ^^^^^^^^^^^^^^^^^^^^^^^^^^
IsADirectoryError: [Errno 21] Is a directory: '/opt/airflow/nyc_od_app_token.txt'
[2025-04-17T01:07:50.049+0000] {logging_mixin.py:190} INFO - Task instance in failure state
[2025-04-17T01:07:50.050+0000] {logging_mixin.py:190} INFO - Task start:2025-04-17 01:07:49.961841+00:00 end:2025-04-17 01:07:50.049612+00:00 duration:0.087771
[2025-04-17T01:07:50.050+0000] {logging_mixin.py:190} INFO - Task:<Task(BranchPythonOperator): fetch_permits_task> dag:<DAG: data_ingestion_gcs_dag> dagrun:<DagRun data_ingestion_gcs_dag @ 2025-04-16 00:00:00+00:00: scheduled__2025-04-16T00:00:00+00:00, state:running, queued_at: 2025-04-17 01:02:40.039674+00:00. externally triggered: False>
[2025-04-17T01:07:50.050+0000] {logging_mixin.py:190} INFO - Failure caused by [Errno 21] Is a directory: '/opt/***/nyc_od_app_token.txt'
[2025-04-17T01:07:50.050+0000] {taskinstance.py:1226} INFO - Marking task as FAILED. dag_id=data_ingestion_gcs_dag, task_id=fetch_permits_task, run_id=scheduled__2025-04-16T00:00:00+00:00, execution_date=20250416T000000, start_date=20250417T010749, end_date=20250417T010750
[2025-04-17T01:07:50.062+0000] {taskinstance.py:341} INFO - ::group::Post task execution logs
[2025-04-17T01:07:50.062+0000] {standard_task_runner.py:124} ERROR - Failed to execute job 5 for task fetch_permits_task ([Errno 21] Is a directory: '/opt/airflow/nyc_od_app_token.txt'; 166)
Traceback (most recent call last):
  File "/home/airflow/.local/lib/python3.12/site-packages/airflow/task/task_runner/standard_task_runner.py", line 117, in _start_by_fork
    ret = args.func(args, dag=self.dag)
          ^^^^^^^^^^^^^^^^^^^^^^^^^^^^^
  File "/home/airflow/.local/lib/python3.12/site-packages/airflow/cli/cli_config.py", line 49, in command
    return func(*args, **kwargs)
           ^^^^^^^^^^^^^^^^^^^^^
  File "/home/airflow/.local/lib/python3.12/site-packages/airflow/utils/cli.py", line 116, in wrapper
    return f(*args, **kwargs)
           ^^^^^^^^^^^^^^^^^^
  File "/home/airflow/.local/lib/python3.12/site-packages/airflow/cli/commands/task_command.py", line 483, in task_run
    task_return_code = _run_task_by_selected_method(args, _dag, ti)
                       ^^^^^^^^^^^^^^^^^^^^^^^^^^^^^^^^^^^^^^^^^^^^
  File "/home/airflow/.local/lib/python3.12/site-packages/airflow/cli/commands/task_command.py", line 256, in _run_task_by_selected_method
    return _run_raw_task(args, ti)
           ^^^^^^^^^^^^^^^^^^^^^^^
  File "/home/airflow/.local/lib/python3.12/site-packages/airflow/cli/commands/task_command.py", line 341, in _run_raw_task
    return ti._run_raw_task(
           ^^^^^^^^^^^^^^^^^
  File "/home/airflow/.local/lib/python3.12/site-packages/airflow/utils/session.py", line 97, in wrapper
    return func(*args, session=session, **kwargs)
           ^^^^^^^^^^^^^^^^^^^^^^^^^^^^^^^^^^^^^^
  File "/home/airflow/.local/lib/python3.12/site-packages/airflow/models/taskinstance.py", line 3006, in _run_raw_task
    return _run_raw_task(
           ^^^^^^^^^^^^^^
  File "/home/airflow/.local/lib/python3.12/site-packages/airflow/models/taskinstance.py", line 274, in _run_raw_task
    TaskInstance._execute_task_with_callbacks(
  File "/home/airflow/.local/lib/python3.12/site-packages/airflow/models/taskinstance.py", line 3161, in _execute_task_with_callbacks
    result = self._execute_task(context, task_orig)
             ^^^^^^^^^^^^^^^^^^^^^^^^^^^^^^^^^^^^^^
  File "/home/airflow/.local/lib/python3.12/site-packages/airflow/models/taskinstance.py", line 3185, in _execute_task
    return _execute_task(self, context, task_orig)
           ^^^^^^^^^^^^^^^^^^^^^^^^^^^^^^^^^^^^^^^
  File "/home/airflow/.local/lib/python3.12/site-packages/airflow/models/taskinstance.py", line 768, in _execute_task
    result = _execute_callable(context=context, **execute_callable_kwargs)
             ^^^^^^^^^^^^^^^^^^^^^^^^^^^^^^^^^^^^^^^^^^^^^^^^^^^^^^^^^^^^^
  File "/home/airflow/.local/lib/python3.12/site-packages/airflow/models/taskinstance.py", line 734, in _execute_callable
    return ExecutionCallableRunner(
           ^^^^^^^^^^^^^^^^^^^^^^^^
  File "/home/airflow/.local/lib/python3.12/site-packages/airflow/utils/operator_helpers.py", line 252, in run
    return self.func(*args, **kwargs)
           ^^^^^^^^^^^^^^^^^^^^^^^^^^
  File "/home/airflow/.local/lib/python3.12/site-packages/airflow/models/baseoperator.py", line 424, in wrapper
    return func(self, *args, **kwargs)
           ^^^^^^^^^^^^^^^^^^^^^^^^^^^
  File "/home/airflow/.local/lib/python3.12/site-packages/airflow/operators/python.py", line 274, in execute
    return self.do_branch(context, super().execute(context))
                                   ^^^^^^^^^^^^^^^^^^^^^^^^
  File "/home/airflow/.local/lib/python3.12/site-packages/airflow/models/baseoperator.py", line 424, in wrapper
    return func(self, *args, **kwargs)
           ^^^^^^^^^^^^^^^^^^^^^^^^^^^
  File "/home/airflow/.local/lib/python3.12/site-packages/airflow/operators/python.py", line 238, in execute
    return_value = self.execute_callable()
                   ^^^^^^^^^^^^^^^^^^^^^^^
  File "/home/airflow/.local/lib/python3.12/site-packages/airflow/operators/python.py", line 256, in execute_callable
    return runner.run(*self.op_args, **self.op_kwargs)
           ^^^^^^^^^^^^^^^^^^^^^^^^^^^^^^^^^^^^^^^^^^^
  File "/home/airflow/.local/lib/python3.12/site-packages/airflow/utils/operator_helpers.py", line 252, in run
    return self.func(*args, **kwargs)
           ^^^^^^^^^^^^^^^^^^^^^^^^^^
  File "/opt/airflow/dags/data_ingestion_gcs_dag.py", line 70, in fetch_permits
    with open(token_file_path, "r") as file:
         ^^^^^^^^^^^^^^^^^^^^^^^^^^
IsADirectoryError: [Errno 21] Is a directory: '/opt/airflow/nyc_od_app_token.txt'
[2025-04-17T01:07:50.076+0000] {local_task_job_runner.py:266} INFO - Task exited with return code 1
[2025-04-17T01:07:50.089+0000] {taskinstance.py:3901} INFO - 0 downstream tasks scheduled from follow-on schedule check
[2025-04-17T01:07:50.091+0000] {local_task_job_runner.py:245} INFO - ::endgroup::
