[2025-04-07T01:08:40.317+0000] {local_task_job_runner.py:123} INFO - ::group::Pre task execution logs
[2025-04-07T01:08:40.329+0000] {taskinstance.py:2614} INFO - Dependencies all met for dep_context=non-requeueable deps ti=<TaskInstance: data_ingestion_gcs_dag.bigquery_external_table_task scheduled__2025-04-06T00:00:00+00:00 [queued]>
[2025-04-07T01:08:40.334+0000] {taskinstance.py:2614} INFO - Dependencies all met for dep_context=requeueable deps ti=<TaskInstance: data_ingestion_gcs_dag.bigquery_external_table_task scheduled__2025-04-06T00:00:00+00:00 [queued]>
[2025-04-07T01:08:40.334+0000] {taskinstance.py:2867} INFO - Starting attempt 1 of 2
[2025-04-07T01:08:40.339+0000] {taskinstance.py:2890} INFO - Executing <Task(BigQueryCreateExternalTableOperator): bigquery_external_table_task> on 2025-04-06 00:00:00+00:00
[2025-04-07T01:08:40.344+0000] {warnings.py:112} WARNING - /home/***/.local/lib/python3.12/site-packages/***/task/task_runner/standard_task_runner.py:70: DeprecationWarning: This process (pid=104) is multi-threaded, use of fork() may lead to deadlocks in the child.
  pid = os.fork()

[2025-04-07T01:08:40.345+0000] {standard_task_runner.py:72} INFO - Started process 106 to run task
[2025-04-07T01:08:40.345+0000] {standard_task_runner.py:104} INFO - Running: ['***', 'tasks', 'run', 'data_ingestion_gcs_dag', 'bigquery_external_table_task', 'scheduled__2025-04-06T00:00:00+00:00', '--job-id', '6', '--raw', '--subdir', 'DAGS_FOLDER/data_ingestion_gcs_dag.py', '--cfg-path', '/tmp/tmptbf6_kmc']
[2025-04-07T01:08:40.346+0000] {standard_task_runner.py:105} INFO - Job 6: Subtask bigquery_external_table_task
[2025-04-07T01:08:40.372+0000] {task_command.py:467} INFO - Running <TaskInstance: data_ingestion_gcs_dag.bigquery_external_table_task scheduled__2025-04-06T00:00:00+00:00 [running]> on host 628caec663d6
[2025-04-07T01:08:40.411+0000] {taskinstance.py:3134} INFO - Exporting env vars: AIRFLOW_CTX_DAG_OWNER='***' AIRFLOW_CTX_DAG_ID='data_ingestion_gcs_dag' AIRFLOW_CTX_TASK_ID='bigquery_external_table_task' AIRFLOW_CTX_EXECUTION_DATE='2025-04-06T00:00:00+00:00' AIRFLOW_CTX_TRY_NUMBER='1' AIRFLOW_CTX_DAG_RUN_ID='scheduled__2025-04-06T00:00:00+00:00'
[2025-04-07T01:08:40.412+0000] {logging_mixin.py:190} INFO - Task instance is in running state
[2025-04-07T01:08:40.412+0000] {logging_mixin.py:190} INFO -  Previous state of the Task instance: queued
[2025-04-07T01:08:40.412+0000] {logging_mixin.py:190} INFO - Current task name:bigquery_external_table_task state:running start_date:2025-04-07 01:08:40.329813+00:00
[2025-04-07T01:08:40.412+0000] {logging_mixin.py:190} INFO - Dag name:data_ingestion_gcs_dag and current dag run status:running
[2025-04-07T01:08:40.412+0000] {taskinstance.py:732} INFO - ::endgroup::
[2025-04-07T01:08:40.413+0000] {crypto.py:82} WARNING - empty cryptography key - values will not be stored encrypted.
[2025-04-07T01:08:40.413+0000] {connection.py:277} WARNING - Connection schemes (type: google_cloud_platform) shall not contain '_' according to RFC3986.
[2025-04-07T01:08:40.414+0000] {base.py:84} INFO - Retrieving connection 'google_cloud_default'
[2025-04-07T01:08:40.794+0000] {taskinstance.py:3313} ERROR - Task failed with exception
Traceback (most recent call last):
  File "/home/airflow/.local/lib/python3.12/site-packages/airflow/models/taskinstance.py", line 768, in _execute_task
    result = _execute_callable(context=context, **execute_callable_kwargs)
             ^^^^^^^^^^^^^^^^^^^^^^^^^^^^^^^^^^^^^^^^^^^^^^^^^^^^^^^^^^^^^
  File "/home/airflow/.local/lib/python3.12/site-packages/airflow/models/taskinstance.py", line 734, in _execute_callable
    return ExecutionCallableRunner(
           ^^^^^^^^^^^^^^^^^^^^^^^^
  File "/home/airflow/.local/lib/python3.12/site-packages/airflow/utils/operator_helpers.py", line 252, in run
    return self.func(*args, **kwargs)
           ^^^^^^^^^^^^^^^^^^^^^^^^^^
  File "/home/airflow/.local/lib/python3.12/site-packages/airflow/models/baseoperator.py", line 424, in wrapper
    return func(self, *args, **kwargs)
           ^^^^^^^^^^^^^^^^^^^^^^^^^^^
  File "/home/airflow/.local/lib/python3.12/site-packages/airflow/providers/google/cloud/operators/bigquery.py", line 1656, in execute
    self._table = bq_hook.create_empty_table(
                  ^^^^^^^^^^^^^^^^^^^^^^^^^^^
  File "/home/airflow/.local/lib/python3.12/site-packages/airflow/providers/google/common/hooks/base_google.py", line 553, in inner_wrapper
    return func(self, *args, **kwargs)
           ^^^^^^^^^^^^^^^^^^^^^^^^^^^
  File "/home/airflow/.local/lib/python3.12/site-packages/airflow/providers/google/cloud/hooks/bigquery.py", line 457, in create_empty_table
    return self.get_client(project_id=project_id, location=location).create_table(
           ^^^^^^^^^^^^^^^^^^^^^^^^^^^^^^^^^^^^^^^^^^^^^^^^^^^^^^^^^^^^^^^^^^^^^^^
  File "/home/airflow/.local/lib/python3.12/site-packages/google/cloud/bigquery/client.py", line 797, in create_table
    api_response = self._call_api(
                   ^^^^^^^^^^^^^^^
  File "/home/airflow/.local/lib/python3.12/site-packages/google/cloud/bigquery/client.py", line 831, in _call_api
    return call()
           ^^^^^^
  File "/home/airflow/.local/lib/python3.12/site-packages/google/api_core/retry/retry_unary.py", line 293, in retry_wrapped_func
    return retry_target(
           ^^^^^^^^^^^^^
  File "/home/airflow/.local/lib/python3.12/site-packages/google/api_core/retry/retry_unary.py", line 153, in retry_target
    _retry_error_helper(
  File "/home/airflow/.local/lib/python3.12/site-packages/google/api_core/retry/retry_base.py", line 212, in _retry_error_helper
    raise final_exc from source_exc
  File "/home/airflow/.local/lib/python3.12/site-packages/google/api_core/retry/retry_unary.py", line 144, in retry_target
    result = target()
             ^^^^^^^^
  File "/home/airflow/.local/lib/python3.12/site-packages/google/cloud/_http/__init__.py", line 494, in api_request
    raise exceptions.from_http_response(response)
google.api_core.exceptions.NotFound: 404 POST https://bigquery.googleapis.com/bigquery/v2/projects/nyc-projects-455321/datasets/trips_data_all/tables?prettyPrint=false: Not found: Dataset nyc-projects-455321:trips_data_all
[2025-04-07T01:08:40.803+0000] {logging_mixin.py:190} INFO - Task instance in failure state
[2025-04-07T01:08:40.803+0000] {logging_mixin.py:190} INFO - Task start:2025-04-07 01:08:40.329813+00:00 end:2025-04-07 01:08:40.802878+00:00 duration:0.473065
[2025-04-07T01:08:40.803+0000] {logging_mixin.py:190} INFO - Task:<Task(BigQueryCreateExternalTableOperator): bigquery_external_table_task> dag:<DAG: data_ingestion_gcs_dag> dagrun:<DagRun data_ingestion_gcs_dag @ 2025-04-06 00:00:00+00:00: scheduled__2025-04-06T00:00:00+00:00, state:running, queued_at: 2025-04-07 01:08:32.259016+00:00. externally triggered: False>
[2025-04-07T01:08:40.804+0000] {logging_mixin.py:190} INFO - Failure caused by 404 POST https://bigquery.googleapis.com/bigquery/v2/projects/nyc-projects-455321/datasets/trips_data_all/tables?prettyPrint=false: Not found: Dataset nyc-projects-455321:trips_data_all
[2025-04-07T01:08:40.804+0000] {taskinstance.py:1226} INFO - Marking task as UP_FOR_RETRY. dag_id=data_ingestion_gcs_dag, task_id=bigquery_external_table_task, run_id=scheduled__2025-04-06T00:00:00+00:00, execution_date=20250406T000000, start_date=20250407T010840, end_date=20250407T010840
[2025-04-07T01:08:40.822+0000] {taskinstance.py:341} INFO - ::group::Post task execution logs
[2025-04-07T01:08:40.822+0000] {standard_task_runner.py:124} ERROR - Failed to execute job 6 for task bigquery_external_table_task (404 POST https://bigquery.googleapis.com/bigquery/v2/projects/nyc-projects-455321/datasets/trips_data_all/tables?prettyPrint=false: Not found: Dataset nyc-projects-455321:trips_data_all; 106)
Traceback (most recent call last):
  File "/home/airflow/.local/lib/python3.12/site-packages/airflow/task/task_runner/standard_task_runner.py", line 117, in _start_by_fork
    ret = args.func(args, dag=self.dag)
          ^^^^^^^^^^^^^^^^^^^^^^^^^^^^^
  File "/home/airflow/.local/lib/python3.12/site-packages/airflow/cli/cli_config.py", line 49, in command
    return func(*args, **kwargs)
           ^^^^^^^^^^^^^^^^^^^^^
  File "/home/airflow/.local/lib/python3.12/site-packages/airflow/utils/cli.py", line 116, in wrapper
    return f(*args, **kwargs)
           ^^^^^^^^^^^^^^^^^^
  File "/home/airflow/.local/lib/python3.12/site-packages/airflow/cli/commands/task_command.py", line 483, in task_run
    task_return_code = _run_task_by_selected_method(args, _dag, ti)
                       ^^^^^^^^^^^^^^^^^^^^^^^^^^^^^^^^^^^^^^^^^^^^
  File "/home/airflow/.local/lib/python3.12/site-packages/airflow/cli/commands/task_command.py", line 256, in _run_task_by_selected_method
    return _run_raw_task(args, ti)
           ^^^^^^^^^^^^^^^^^^^^^^^
  File "/home/airflow/.local/lib/python3.12/site-packages/airflow/cli/commands/task_command.py", line 341, in _run_raw_task
    return ti._run_raw_task(
           ^^^^^^^^^^^^^^^^^
  File "/home/airflow/.local/lib/python3.12/site-packages/airflow/utils/session.py", line 97, in wrapper
    return func(*args, session=session, **kwargs)
           ^^^^^^^^^^^^^^^^^^^^^^^^^^^^^^^^^^^^^^
  File "/home/airflow/.local/lib/python3.12/site-packages/airflow/models/taskinstance.py", line 3006, in _run_raw_task
    return _run_raw_task(
           ^^^^^^^^^^^^^^
  File "/home/airflow/.local/lib/python3.12/site-packages/airflow/models/taskinstance.py", line 274, in _run_raw_task
    TaskInstance._execute_task_with_callbacks(
  File "/home/airflow/.local/lib/python3.12/site-packages/airflow/models/taskinstance.py", line 3161, in _execute_task_with_callbacks
    result = self._execute_task(context, task_orig)
             ^^^^^^^^^^^^^^^^^^^^^^^^^^^^^^^^^^^^^^
  File "/home/airflow/.local/lib/python3.12/site-packages/airflow/models/taskinstance.py", line 3185, in _execute_task
    return _execute_task(self, context, task_orig)
           ^^^^^^^^^^^^^^^^^^^^^^^^^^^^^^^^^^^^^^^
  File "/home/airflow/.local/lib/python3.12/site-packages/airflow/models/taskinstance.py", line 768, in _execute_task
    result = _execute_callable(context=context, **execute_callable_kwargs)
             ^^^^^^^^^^^^^^^^^^^^^^^^^^^^^^^^^^^^^^^^^^^^^^^^^^^^^^^^^^^^^
  File "/home/airflow/.local/lib/python3.12/site-packages/airflow/models/taskinstance.py", line 734, in _execute_callable
    return ExecutionCallableRunner(
           ^^^^^^^^^^^^^^^^^^^^^^^^
  File "/home/airflow/.local/lib/python3.12/site-packages/airflow/utils/operator_helpers.py", line 252, in run
    return self.func(*args, **kwargs)
           ^^^^^^^^^^^^^^^^^^^^^^^^^^
  File "/home/airflow/.local/lib/python3.12/site-packages/airflow/models/baseoperator.py", line 424, in wrapper
    return func(self, *args, **kwargs)
           ^^^^^^^^^^^^^^^^^^^^^^^^^^^
  File "/home/airflow/.local/lib/python3.12/site-packages/airflow/providers/google/cloud/operators/bigquery.py", line 1656, in execute
    self._table = bq_hook.create_empty_table(
                  ^^^^^^^^^^^^^^^^^^^^^^^^^^^
  File "/home/airflow/.local/lib/python3.12/site-packages/airflow/providers/google/common/hooks/base_google.py", line 553, in inner_wrapper
    return func(self, *args, **kwargs)
           ^^^^^^^^^^^^^^^^^^^^^^^^^^^
  File "/home/airflow/.local/lib/python3.12/site-packages/airflow/providers/google/cloud/hooks/bigquery.py", line 457, in create_empty_table
    return self.get_client(project_id=project_id, location=location).create_table(
           ^^^^^^^^^^^^^^^^^^^^^^^^^^^^^^^^^^^^^^^^^^^^^^^^^^^^^^^^^^^^^^^^^^^^^^^
  File "/home/airflow/.local/lib/python3.12/site-packages/google/cloud/bigquery/client.py", line 797, in create_table
    api_response = self._call_api(
                   ^^^^^^^^^^^^^^^
  File "/home/airflow/.local/lib/python3.12/site-packages/google/cloud/bigquery/client.py", line 831, in _call_api
    return call()
           ^^^^^^
  File "/home/airflow/.local/lib/python3.12/site-packages/google/api_core/retry/retry_unary.py", line 293, in retry_wrapped_func
    return retry_target(
           ^^^^^^^^^^^^^
  File "/home/airflow/.local/lib/python3.12/site-packages/google/api_core/retry/retry_unary.py", line 153, in retry_target
    _retry_error_helper(
  File "/home/airflow/.local/lib/python3.12/site-packages/google/api_core/retry/retry_base.py", line 212, in _retry_error_helper
    raise final_exc from source_exc
  File "/home/airflow/.local/lib/python3.12/site-packages/google/api_core/retry/retry_unary.py", line 144, in retry_target
    result = target()
             ^^^^^^^^
  File "/home/airflow/.local/lib/python3.12/site-packages/google/cloud/_http/__init__.py", line 494, in api_request
    raise exceptions.from_http_response(response)
google.api_core.exceptions.NotFound: 404 POST https://bigquery.googleapis.com/bigquery/v2/projects/nyc-projects-455321/datasets/trips_data_all/tables?prettyPrint=false: Not found: Dataset nyc-projects-455321:trips_data_all
[2025-04-07T01:08:40.855+0000] {local_task_job_runner.py:266} INFO - Task exited with return code 1
[2025-04-07T01:08:40.891+0000] {taskinstance.py:3901} INFO - 0 downstream tasks scheduled from follow-on schedule check
[2025-04-07T01:08:40.893+0000] {local_task_job_runner.py:245} INFO - ::endgroup::
