[2025-04-14T05:00:07.717+0000] {local_task_job_runner.py:123} INFO - ::group::Pre task execution logs
[2025-04-14T05:00:07.729+0000] {taskinstance.py:2614} INFO - Dependencies all met for dep_context=non-requeueable deps ti=<TaskInstance: data_ingestion_gcs_dag.fetch_permits_task scheduled__2025-04-13T00:00:00+00:00 [queued]>
[2025-04-14T05:00:07.733+0000] {taskinstance.py:2614} INFO - Dependencies all met for dep_context=requeueable deps ti=<TaskInstance: data_ingestion_gcs_dag.fetch_permits_task scheduled__2025-04-13T00:00:00+00:00 [queued]>
[2025-04-14T05:00:07.734+0000] {taskinstance.py:2867} INFO - Starting attempt 2 of 2
[2025-04-14T05:00:07.740+0000] {taskinstance.py:2890} INFO - Executing <Task(BranchPythonOperator): fetch_permits_task> on 2025-04-13 00:00:00+00:00
[2025-04-14T05:00:07.745+0000] {warnings.py:112} WARNING - /home/***/.local/lib/python3.12/site-packages/***/task/task_runner/standard_task_runner.py:70: DeprecationWarning: This process (pid=262) is multi-threaded, use of fork() may lead to deadlocks in the child.
  pid = os.fork()

[2025-04-14T05:00:07.746+0000] {standard_task_runner.py:72} INFO - Started process 264 to run task
[2025-04-14T05:00:07.747+0000] {standard_task_runner.py:104} INFO - Running: ['***', 'tasks', 'run', 'data_ingestion_gcs_dag', 'fetch_permits_task', 'scheduled__2025-04-13T00:00:00+00:00', '--job-id', '5', '--raw', '--subdir', 'DAGS_FOLDER/data_ingestion_gcs_dag.py', '--cfg-path', '/tmp/tmp7yt4k40e']
[2025-04-14T05:00:07.747+0000] {standard_task_runner.py:105} INFO - Job 5: Subtask fetch_permits_task
[2025-04-14T05:00:07.772+0000] {task_command.py:467} INFO - Running <TaskInstance: data_ingestion_gcs_dag.fetch_permits_task scheduled__2025-04-13T00:00:00+00:00 [running]> on host 8f3f7397b438
[2025-04-14T05:00:07.809+0000] {taskinstance.py:3134} INFO - Exporting env vars: AIRFLOW_CTX_DAG_OWNER='***' AIRFLOW_CTX_DAG_ID='data_ingestion_gcs_dag' AIRFLOW_CTX_TASK_ID='fetch_permits_task' AIRFLOW_CTX_EXECUTION_DATE='2025-04-13T00:00:00+00:00' AIRFLOW_CTX_TRY_NUMBER='2' AIRFLOW_CTX_DAG_RUN_ID='scheduled__2025-04-13T00:00:00+00:00'
[2025-04-14T05:00:07.810+0000] {logging_mixin.py:190} INFO - Task instance is in running state
[2025-04-14T05:00:07.810+0000] {logging_mixin.py:190} INFO -  Previous state of the Task instance: queued
[2025-04-14T05:00:07.810+0000] {logging_mixin.py:190} INFO - Current task name:fetch_permits_task state:running start_date:2025-04-14 05:00:07.729352+00:00
[2025-04-14T05:00:07.810+0000] {logging_mixin.py:190} INFO - Dag name:data_ingestion_gcs_dag and current dag run status:running
[2025-04-14T05:00:07.810+0000] {taskinstance.py:732} INFO - ::endgroup::
[2025-04-14T05:00:07.810+0000] {baseoperator.py:423} WARNING - BranchPythonOperator.execute cannot be called outside TaskInstance!
[2025-04-14T05:00:07.816+0000] {logging_mixin.py:190} INFO - Fetching records for 2020-04-29 (offset=0)
[2025-04-14T05:00:11.079+0000] {logging_mixin.py:190} INFO - Fetching records for 2020-04-30 (offset=0)
[2025-04-14T05:00:11.516+0000] {logging_mixin.py:190} INFO - Fetching records for 2020-05-01 (offset=0)
[2025-04-14T05:00:11.887+0000] {logging_mixin.py:190} INFO - Fetching records for 2020-05-02 (offset=0)
[2025-04-14T05:00:12.204+0000] {logging_mixin.py:190} INFO - Fetching records for 2020-05-03 (offset=0)
[2025-04-14T05:00:12.650+0000] {logging_mixin.py:190} INFO - Fetching records for 2020-05-04 (offset=0)
[2025-04-14T05:00:13.043+0000] {logging_mixin.py:190} INFO - Fetching records for 2020-05-05 (offset=0)
[2025-04-14T05:00:13.406+0000] {logging_mixin.py:190} INFO - Fetching records for 2020-05-06 (offset=0)
[2025-04-14T05:00:13.873+0000] {logging_mixin.py:190} INFO - Fetching records for 2020-05-07 (offset=0)
[2025-04-14T05:00:14.247+0000] {logging_mixin.py:190} INFO - Fetching records for 2020-05-08 (offset=0)
[2025-04-14T05:00:14.612+0000] {logging_mixin.py:190} INFO - Fetching records for 2020-05-09 (offset=0)
[2025-04-14T05:00:14.949+0000] {logging_mixin.py:190} INFO - Fetching records for 2020-05-10 (offset=0)
[2025-04-14T05:00:15.297+0000] {logging_mixin.py:190} INFO - Fetching records for 2020-05-11 (offset=0)
[2025-04-14T05:00:15.631+0000] {logging_mixin.py:190} INFO - Fetching records for 2020-05-12 (offset=0)
[2025-04-14T05:00:15.971+0000] {logging_mixin.py:190} INFO - Fetching records for 2020-05-13 (offset=0)
[2025-04-14T05:00:16.440+0000] {logging_mixin.py:190} INFO - Fetching records for 2020-05-14 (offset=0)
[2025-04-14T05:00:16.840+0000] {logging_mixin.py:190} INFO - Fetching records for 2020-05-15 (offset=0)
[2025-04-14T05:00:17.254+0000] {logging_mixin.py:190} INFO - Fetching records for 2020-05-16 (offset=0)
[2025-04-14T05:00:17.721+0000] {logging_mixin.py:190} INFO - Fetching records for 2020-05-17 (offset=0)
[2025-04-14T05:00:17.917+0000] {logging_mixin.py:190} INFO - Fetching records for 2020-05-18 (offset=0)
[2025-04-14T05:00:18.265+0000] {logging_mixin.py:190} INFO - Fetching records for 2020-05-19 (offset=0)
[2025-04-14T05:00:23.629+0000] {logging_mixin.py:190} INFO - Fetching records for 2020-05-20 (offset=0)
[2025-04-14T05:00:23.983+0000] {logging_mixin.py:190} INFO - Fetching records for 2020-05-21 (offset=0)
[2025-04-14T05:00:24.384+0000] {logging_mixin.py:190} INFO - Fetching records for 2020-05-22 (offset=0)
[2025-04-14T05:00:24.714+0000] {logging_mixin.py:190} INFO - Fetching records for 2020-05-23 (offset=0)
[2025-04-14T05:00:25.022+0000] {logging_mixin.py:190} INFO - Fetching records for 2020-05-24 (offset=0)
[2025-04-14T05:00:25.231+0000] {logging_mixin.py:190} INFO - Fetching records for 2020-05-25 (offset=0)
[2025-04-14T05:00:25.576+0000] {logging_mixin.py:190} INFO - Fetching records for 2020-05-26 (offset=0)
[2025-04-14T05:00:25.914+0000] {logging_mixin.py:190} INFO - Fetching records for 2020-05-27 (offset=0)
[2025-04-14T05:00:26.302+0000] {logging_mixin.py:190} INFO - Fetching records for 2020-05-28 (offset=0)
[2025-04-14T05:00:26.662+0000] {logging_mixin.py:190} INFO - Fetching records for 2020-05-29 (offset=0)
[2025-04-14T05:00:26.999+0000] {logging_mixin.py:190} INFO - Fetching records for 2020-05-30 (offset=0)
[2025-04-14T05:00:27.307+0000] {logging_mixin.py:190} INFO - Fetching records for 2020-05-31 (offset=0)
[2025-04-14T05:00:27.619+0000] {logging_mixin.py:190} INFO - Fetching records for 2020-06-01 (offset=0)
[2025-04-14T05:00:27.991+0000] {logging_mixin.py:190} INFO - Fetching records for 2020-06-02 (offset=0)
[2025-04-14T05:00:28.357+0000] {logging_mixin.py:190} INFO - Fetching records for 2020-06-03 (offset=0)
[2025-04-14T05:00:28.740+0000] {logging_mixin.py:190} INFO - Fetching records for 2020-06-04 (offset=0)
[2025-04-14T05:00:29.130+0000] {logging_mixin.py:190} INFO - Fetching records for 2020-06-05 (offset=0)
[2025-04-14T05:00:37.210+0000] {logging_mixin.py:190} INFO - Fetching records for 2020-06-06 (offset=0)
[2025-04-14T05:00:37.547+0000] {logging_mixin.py:190} INFO - Fetching records for 2020-06-07 (offset=0)
[2025-04-14T05:00:37.870+0000] {logging_mixin.py:190} INFO - Fetching records for 2020-06-08 (offset=0)
[2025-04-14T05:00:38.267+0000] {logging_mixin.py:190} INFO - Fetching records for 2020-06-09 (offset=0)
[2025-04-14T05:00:38.672+0000] {logging_mixin.py:190} INFO - Fetching records for 2020-06-10 (offset=0)
[2025-04-14T05:00:39.063+0000] {logging_mixin.py:190} INFO - Fetching records for 2020-06-11 (offset=0)
[2025-04-14T05:00:39.517+0000] {logging_mixin.py:190} INFO - Fetching records for 2020-06-12 (offset=0)
[2025-04-14T05:00:39.893+0000] {logging_mixin.py:190} INFO - Fetching records for 2020-06-13 (offset=0)
[2025-04-14T05:00:40.236+0000] {logging_mixin.py:190} INFO - Fetching records for 2020-06-14 (offset=0)
[2025-04-14T05:00:40.561+0000] {logging_mixin.py:190} INFO - Fetching records for 2020-06-15 (offset=0)
[2025-04-14T05:00:40.993+0000] {logging_mixin.py:190} INFO - Fetching records for 2020-06-16 (offset=0)
[2025-04-14T05:00:41.380+0000] {logging_mixin.py:190} INFO - Fetching records for 2020-06-17 (offset=0)
[2025-04-14T05:00:41.780+0000] {logging_mixin.py:190} INFO - Fetching records for 2020-06-18 (offset=0)
[2025-04-14T05:00:42.211+0000] {logging_mixin.py:190} INFO - Fetching records for 2020-06-19 (offset=0)
[2025-04-14T05:00:42.573+0000] {logging_mixin.py:190} INFO - Fetching records for 2020-06-20 (offset=0)
[2025-04-14T05:00:42.877+0000] {logging_mixin.py:190} INFO - Fetching records for 2020-06-21 (offset=0)
[2025-04-14T05:00:43.196+0000] {logging_mixin.py:190} INFO - Fetching records for 2020-06-22 (offset=0)
[2025-04-14T05:00:43.646+0000] {logging_mixin.py:190} INFO - Fetching records for 2020-06-23 (offset=0)
[2025-04-14T05:00:44.405+0000] {logging_mixin.py:190} INFO - Fetching records for 2020-06-24 (offset=0)
[2025-04-14T05:00:44.853+0000] {logging_mixin.py:190} INFO - Fetching records for 2020-06-25 (offset=0)
[2025-04-14T05:00:45.259+0000] {logging_mixin.py:190} INFO - Fetching records for 2020-06-26 (offset=0)
[2025-04-14T05:00:45.791+0000] {logging_mixin.py:190} INFO - Fetching records for 2020-06-27 (offset=0)
[2025-04-14T05:00:55.987+0000] {taskinstance.py:3313} ERROR - Task failed with exception
Traceback (most recent call last):
  File "/home/airflow/.local/lib/python3.12/site-packages/urllib3/connectionpool.py", line 534, in _make_request
    response = conn.getresponse()
               ^^^^^^^^^^^^^^^^^^
  File "/home/airflow/.local/lib/python3.12/site-packages/urllib3/connection.py", line 516, in getresponse
    httplib_response = super().getresponse()
                       ^^^^^^^^^^^^^^^^^^^^^
  File "/usr/local/lib/python3.12/http/client.py", line 1430, in getresponse
    response.begin()
  File "/usr/local/lib/python3.12/http/client.py", line 331, in begin
    version, status, reason = self._read_status()
                              ^^^^^^^^^^^^^^^^^^^
  File "/usr/local/lib/python3.12/http/client.py", line 292, in _read_status
    line = str(self.fp.readline(_MAXLINE + 1), "iso-8859-1")
               ^^^^^^^^^^^^^^^^^^^^^^^^^^^^^^
  File "/usr/local/lib/python3.12/socket.py", line 720, in readinto
    return self._sock.recv_into(b)
           ^^^^^^^^^^^^^^^^^^^^^^^
  File "/usr/local/lib/python3.12/ssl.py", line 1251, in recv_into
    return self.read(nbytes, buffer)
           ^^^^^^^^^^^^^^^^^^^^^^^^^
  File "/usr/local/lib/python3.12/ssl.py", line 1103, in read
    return self._sslobj.read(len, buffer)
           ^^^^^^^^^^^^^^^^^^^^^^^^^^^^^^
TimeoutError: The read operation timed out

The above exception was the direct cause of the following exception:

Traceback (most recent call last):
  File "/home/airflow/.local/lib/python3.12/site-packages/requests/adapters.py", line 667, in send
    resp = conn.urlopen(
           ^^^^^^^^^^^^^
  File "/home/airflow/.local/lib/python3.12/site-packages/urllib3/connectionpool.py", line 841, in urlopen
    retries = retries.increment(
              ^^^^^^^^^^^^^^^^^^
  File "/home/airflow/.local/lib/python3.12/site-packages/urllib3/util/retry.py", line 474, in increment
    raise reraise(type(error), error, _stacktrace)
          ^^^^^^^^^^^^^^^^^^^^^^^^^^^^^^^^^^^^^^^^
  File "/home/airflow/.local/lib/python3.12/site-packages/urllib3/util/util.py", line 39, in reraise
    raise value
  File "/home/airflow/.local/lib/python3.12/site-packages/urllib3/connectionpool.py", line 787, in urlopen
    response = self._make_request(
               ^^^^^^^^^^^^^^^^^^^
  File "/home/airflow/.local/lib/python3.12/site-packages/urllib3/connectionpool.py", line 536, in _make_request
    self._raise_timeout(err=e, url=url, timeout_value=read_timeout)
  File "/home/airflow/.local/lib/python3.12/site-packages/urllib3/connectionpool.py", line 367, in _raise_timeout
    raise ReadTimeoutError(
urllib3.exceptions.ReadTimeoutError: HTTPSConnectionPool(host='data.cityofnewyork.us', port=443): Read timed out. (read timeout=10)

During handling of the above exception, another exception occurred:

Traceback (most recent call last):
  File "/home/airflow/.local/lib/python3.12/site-packages/airflow/models/taskinstance.py", line 768, in _execute_task
    result = _execute_callable(context=context, **execute_callable_kwargs)
             ^^^^^^^^^^^^^^^^^^^^^^^^^^^^^^^^^^^^^^^^^^^^^^^^^^^^^^^^^^^^^
  File "/home/airflow/.local/lib/python3.12/site-packages/airflow/models/taskinstance.py", line 734, in _execute_callable
    return ExecutionCallableRunner(
           ^^^^^^^^^^^^^^^^^^^^^^^^
  File "/home/airflow/.local/lib/python3.12/site-packages/airflow/utils/operator_helpers.py", line 252, in run
    return self.func(*args, **kwargs)
           ^^^^^^^^^^^^^^^^^^^^^^^^^^
  File "/home/airflow/.local/lib/python3.12/site-packages/airflow/models/baseoperator.py", line 424, in wrapper
    return func(self, *args, **kwargs)
           ^^^^^^^^^^^^^^^^^^^^^^^^^^^
  File "/home/airflow/.local/lib/python3.12/site-packages/airflow/operators/python.py", line 274, in execute
    return self.do_branch(context, super().execute(context))
                                   ^^^^^^^^^^^^^^^^^^^^^^^^
  File "/home/airflow/.local/lib/python3.12/site-packages/airflow/models/baseoperator.py", line 424, in wrapper
    return func(self, *args, **kwargs)
           ^^^^^^^^^^^^^^^^^^^^^^^^^^^
  File "/home/airflow/.local/lib/python3.12/site-packages/airflow/operators/python.py", line 238, in execute
    return_value = self.execute_callable()
                   ^^^^^^^^^^^^^^^^^^^^^^^
  File "/home/airflow/.local/lib/python3.12/site-packages/airflow/operators/python.py", line 256, in execute_callable
    return runner.run(*self.op_args, **self.op_kwargs)
           ^^^^^^^^^^^^^^^^^^^^^^^^^^^^^^^^^^^^^^^^^^^
  File "/home/airflow/.local/lib/python3.12/site-packages/airflow/utils/operator_helpers.py", line 252, in run
    return self.func(*args, **kwargs)
           ^^^^^^^^^^^^^^^^^^^^^^^^^^
  File "/opt/airflow/dags/data_ingestion_gcs_dag.py", line 86, in fetch_permits
    results = client.get(
              ^^^^^^^^^^^
  File "/home/airflow/.local/lib/python3.12/site-packages/sodapy/socrata.py", line 412, in get
    response = self._perform_request(
               ^^^^^^^^^^^^^^^^^^^^^^
  File "/home/airflow/.local/lib/python3.12/site-packages/sodapy/socrata.py", line 551, in _perform_request
    response = getattr(self.session, request_type)(uri, **kwargs)
               ^^^^^^^^^^^^^^^^^^^^^^^^^^^^^^^^^^^^^^^^^^^^^^^^^^
  File "/home/airflow/.local/lib/python3.12/site-packages/requests/sessions.py", line 602, in get
    return self.request("GET", url, **kwargs)
           ^^^^^^^^^^^^^^^^^^^^^^^^^^^^^^^^^^
  File "/home/airflow/.local/lib/python3.12/site-packages/requests/sessions.py", line 589, in request
    resp = self.send(prep, **send_kwargs)
           ^^^^^^^^^^^^^^^^^^^^^^^^^^^^^^
  File "/home/airflow/.local/lib/python3.12/site-packages/requests/sessions.py", line 703, in send
    r = adapter.send(request, **kwargs)
        ^^^^^^^^^^^^^^^^^^^^^^^^^^^^^^^
  File "/home/airflow/.local/lib/python3.12/site-packages/requests/adapters.py", line 713, in send
    raise ReadTimeout(e, request=request)
requests.exceptions.ReadTimeout: HTTPSConnectionPool(host='data.cityofnewyork.us', port=443): Read timed out. (read timeout=10)
[2025-04-14T05:00:56.018+0000] {logging_mixin.py:190} INFO - Task instance in failure state
[2025-04-14T05:00:56.020+0000] {logging_mixin.py:190} INFO - Task start:2025-04-14 05:00:07.729352+00:00 end:2025-04-14 05:00:56.017001+00:00 duration:48.287649
[2025-04-14T05:00:56.022+0000] {logging_mixin.py:190} INFO - Task:<Task(BranchPythonOperator): fetch_permits_task> dag:<DAG: data_ingestion_gcs_dag> dagrun:<DagRun data_ingestion_gcs_dag @ 2025-04-13 00:00:00+00:00: scheduled__2025-04-13T00:00:00+00:00, state:running, queued_at: 2025-04-14 04:47:22.151897+00:00. externally triggered: False>
[2025-04-14T05:00:56.024+0000] {logging_mixin.py:190} INFO - Failure caused by HTTPSConnectionPool(host='data.cityofnewyork.us', port=443): Read timed out. (read timeout=10)
[2025-04-14T05:00:56.025+0000] {taskinstance.py:1226} INFO - Marking task as FAILED. dag_id=data_ingestion_gcs_dag, task_id=fetch_permits_task, run_id=scheduled__2025-04-13T00:00:00+00:00, execution_date=20250413T000000, start_date=20250414T050007, end_date=20250414T050056
[2025-04-14T05:00:56.069+0000] {taskinstance.py:341} INFO - ::group::Post task execution logs
[2025-04-14T05:00:56.070+0000] {standard_task_runner.py:124} ERROR - Failed to execute job 5 for task fetch_permits_task (HTTPSConnectionPool(host='data.cityofnewyork.us', port=443): Read timed out. (read timeout=10); 264)
Traceback (most recent call last):
  File "/home/airflow/.local/lib/python3.12/site-packages/urllib3/connectionpool.py", line 534, in _make_request
    response = conn.getresponse()
               ^^^^^^^^^^^^^^^^^^
  File "/home/airflow/.local/lib/python3.12/site-packages/urllib3/connection.py", line 516, in getresponse
    httplib_response = super().getresponse()
                       ^^^^^^^^^^^^^^^^^^^^^
  File "/usr/local/lib/python3.12/http/client.py", line 1430, in getresponse
    response.begin()
  File "/usr/local/lib/python3.12/http/client.py", line 331, in begin
    version, status, reason = self._read_status()
                              ^^^^^^^^^^^^^^^^^^^
  File "/usr/local/lib/python3.12/http/client.py", line 292, in _read_status
    line = str(self.fp.readline(_MAXLINE + 1), "iso-8859-1")
               ^^^^^^^^^^^^^^^^^^^^^^^^^^^^^^
  File "/usr/local/lib/python3.12/socket.py", line 720, in readinto
    return self._sock.recv_into(b)
           ^^^^^^^^^^^^^^^^^^^^^^^
  File "/usr/local/lib/python3.12/ssl.py", line 1251, in recv_into
    return self.read(nbytes, buffer)
           ^^^^^^^^^^^^^^^^^^^^^^^^^
  File "/usr/local/lib/python3.12/ssl.py", line 1103, in read
    return self._sslobj.read(len, buffer)
           ^^^^^^^^^^^^^^^^^^^^^^^^^^^^^^
TimeoutError: The read operation timed out

The above exception was the direct cause of the following exception:

Traceback (most recent call last):
  File "/home/airflow/.local/lib/python3.12/site-packages/requests/adapters.py", line 667, in send
    resp = conn.urlopen(
           ^^^^^^^^^^^^^
  File "/home/airflow/.local/lib/python3.12/site-packages/urllib3/connectionpool.py", line 841, in urlopen
    retries = retries.increment(
              ^^^^^^^^^^^^^^^^^^
  File "/home/airflow/.local/lib/python3.12/site-packages/urllib3/util/retry.py", line 474, in increment
    raise reraise(type(error), error, _stacktrace)
          ^^^^^^^^^^^^^^^^^^^^^^^^^^^^^^^^^^^^^^^^
  File "/home/airflow/.local/lib/python3.12/site-packages/urllib3/util/util.py", line 39, in reraise
    raise value
  File "/home/airflow/.local/lib/python3.12/site-packages/urllib3/connectionpool.py", line 787, in urlopen
    response = self._make_request(
               ^^^^^^^^^^^^^^^^^^^
  File "/home/airflow/.local/lib/python3.12/site-packages/urllib3/connectionpool.py", line 536, in _make_request
    self._raise_timeout(err=e, url=url, timeout_value=read_timeout)
  File "/home/airflow/.local/lib/python3.12/site-packages/urllib3/connectionpool.py", line 367, in _raise_timeout
    raise ReadTimeoutError(
urllib3.exceptions.ReadTimeoutError: HTTPSConnectionPool(host='data.cityofnewyork.us', port=443): Read timed out. (read timeout=10)

During handling of the above exception, another exception occurred:

Traceback (most recent call last):
  File "/home/airflow/.local/lib/python3.12/site-packages/airflow/task/task_runner/standard_task_runner.py", line 117, in _start_by_fork
    ret = args.func(args, dag=self.dag)
          ^^^^^^^^^^^^^^^^^^^^^^^^^^^^^
  File "/home/airflow/.local/lib/python3.12/site-packages/airflow/cli/cli_config.py", line 49, in command
    return func(*args, **kwargs)
           ^^^^^^^^^^^^^^^^^^^^^
  File "/home/airflow/.local/lib/python3.12/site-packages/airflow/utils/cli.py", line 116, in wrapper
    return f(*args, **kwargs)
           ^^^^^^^^^^^^^^^^^^
  File "/home/airflow/.local/lib/python3.12/site-packages/airflow/cli/commands/task_command.py", line 483, in task_run
    task_return_code = _run_task_by_selected_method(args, _dag, ti)
                       ^^^^^^^^^^^^^^^^^^^^^^^^^^^^^^^^^^^^^^^^^^^^
  File "/home/airflow/.local/lib/python3.12/site-packages/airflow/cli/commands/task_command.py", line 256, in _run_task_by_selected_method
    return _run_raw_task(args, ti)
           ^^^^^^^^^^^^^^^^^^^^^^^
  File "/home/airflow/.local/lib/python3.12/site-packages/airflow/cli/commands/task_command.py", line 341, in _run_raw_task
    return ti._run_raw_task(
           ^^^^^^^^^^^^^^^^^
  File "/home/airflow/.local/lib/python3.12/site-packages/airflow/utils/session.py", line 97, in wrapper
    return func(*args, session=session, **kwargs)
           ^^^^^^^^^^^^^^^^^^^^^^^^^^^^^^^^^^^^^^
  File "/home/airflow/.local/lib/python3.12/site-packages/airflow/models/taskinstance.py", line 3006, in _run_raw_task
    return _run_raw_task(
           ^^^^^^^^^^^^^^
  File "/home/airflow/.local/lib/python3.12/site-packages/airflow/models/taskinstance.py", line 274, in _run_raw_task
    TaskInstance._execute_task_with_callbacks(
  File "/home/airflow/.local/lib/python3.12/site-packages/airflow/models/taskinstance.py", line 3161, in _execute_task_with_callbacks
    result = self._execute_task(context, task_orig)
             ^^^^^^^^^^^^^^^^^^^^^^^^^^^^^^^^^^^^^^
  File "/home/airflow/.local/lib/python3.12/site-packages/airflow/models/taskinstance.py", line 3185, in _execute_task
    return _execute_task(self, context, task_orig)
           ^^^^^^^^^^^^^^^^^^^^^^^^^^^^^^^^^^^^^^^
  File "/home/airflow/.local/lib/python3.12/site-packages/airflow/models/taskinstance.py", line 768, in _execute_task
    result = _execute_callable(context=context, **execute_callable_kwargs)
             ^^^^^^^^^^^^^^^^^^^^^^^^^^^^^^^^^^^^^^^^^^^^^^^^^^^^^^^^^^^^^
  File "/home/airflow/.local/lib/python3.12/site-packages/airflow/models/taskinstance.py", line 734, in _execute_callable
    return ExecutionCallableRunner(
           ^^^^^^^^^^^^^^^^^^^^^^^^
  File "/home/airflow/.local/lib/python3.12/site-packages/airflow/utils/operator_helpers.py", line 252, in run
    return self.func(*args, **kwargs)
           ^^^^^^^^^^^^^^^^^^^^^^^^^^
  File "/home/airflow/.local/lib/python3.12/site-packages/airflow/models/baseoperator.py", line 424, in wrapper
    return func(self, *args, **kwargs)
           ^^^^^^^^^^^^^^^^^^^^^^^^^^^
  File "/home/airflow/.local/lib/python3.12/site-packages/airflow/operators/python.py", line 274, in execute
    return self.do_branch(context, super().execute(context))
                                   ^^^^^^^^^^^^^^^^^^^^^^^^
  File "/home/airflow/.local/lib/python3.12/site-packages/airflow/models/baseoperator.py", line 424, in wrapper
    return func(self, *args, **kwargs)
           ^^^^^^^^^^^^^^^^^^^^^^^^^^^
  File "/home/airflow/.local/lib/python3.12/site-packages/airflow/operators/python.py", line 238, in execute
    return_value = self.execute_callable()
                   ^^^^^^^^^^^^^^^^^^^^^^^
  File "/home/airflow/.local/lib/python3.12/site-packages/airflow/operators/python.py", line 256, in execute_callable
    return runner.run(*self.op_args, **self.op_kwargs)
           ^^^^^^^^^^^^^^^^^^^^^^^^^^^^^^^^^^^^^^^^^^^
  File "/home/airflow/.local/lib/python3.12/site-packages/airflow/utils/operator_helpers.py", line 252, in run
    return self.func(*args, **kwargs)
           ^^^^^^^^^^^^^^^^^^^^^^^^^^
  File "/opt/airflow/dags/data_ingestion_gcs_dag.py", line 86, in fetch_permits
    results = client.get(
              ^^^^^^^^^^^
  File "/home/airflow/.local/lib/python3.12/site-packages/sodapy/socrata.py", line 412, in get
    response = self._perform_request(
               ^^^^^^^^^^^^^^^^^^^^^^
  File "/home/airflow/.local/lib/python3.12/site-packages/sodapy/socrata.py", line 551, in _perform_request
    response = getattr(self.session, request_type)(uri, **kwargs)
               ^^^^^^^^^^^^^^^^^^^^^^^^^^^^^^^^^^^^^^^^^^^^^^^^^^
  File "/home/airflow/.local/lib/python3.12/site-packages/requests/sessions.py", line 602, in get
    return self.request("GET", url, **kwargs)
           ^^^^^^^^^^^^^^^^^^^^^^^^^^^^^^^^^^
  File "/home/airflow/.local/lib/python3.12/site-packages/requests/sessions.py", line 589, in request
    resp = self.send(prep, **send_kwargs)
           ^^^^^^^^^^^^^^^^^^^^^^^^^^^^^^
  File "/home/airflow/.local/lib/python3.12/site-packages/requests/sessions.py", line 703, in send
    r = adapter.send(request, **kwargs)
        ^^^^^^^^^^^^^^^^^^^^^^^^^^^^^^^
  File "/home/airflow/.local/lib/python3.12/site-packages/requests/adapters.py", line 713, in send
    raise ReadTimeout(e, request=request)
requests.exceptions.ReadTimeout: HTTPSConnectionPool(host='data.cityofnewyork.us', port=443): Read timed out. (read timeout=10)
[2025-04-14T05:00:56.093+0000] {local_task_job_runner.py:266} INFO - Task exited with return code 1
[2025-04-14T05:00:56.108+0000] {taskinstance.py:3901} INFO - 0 downstream tasks scheduled from follow-on schedule check
[2025-04-14T05:00:56.110+0000] {local_task_job_runner.py:245} INFO - ::endgroup::
[2025-04-14T05:19:30.705+0000] {local_task_job_runner.py:123} INFO - ::group::Pre task execution logs
[2025-04-14T05:19:30.718+0000] {taskinstance.py:2614} INFO - Dependencies all met for dep_context=non-requeueable deps ti=<TaskInstance: data_ingestion_gcs_dag.fetch_permits_task scheduled__2025-04-13T00:00:00+00:00 [queued]>
[2025-04-14T05:19:30.723+0000] {taskinstance.py:2614} INFO - Dependencies all met for dep_context=requeueable deps ti=<TaskInstance: data_ingestion_gcs_dag.fetch_permits_task scheduled__2025-04-13T00:00:00+00:00 [queued]>
[2025-04-14T05:19:30.723+0000] {taskinstance.py:2867} INFO - Starting attempt 2 of 2
[2025-04-14T05:19:30.729+0000] {taskinstance.py:2890} INFO - Executing <Task(BranchPythonOperator): fetch_permits_task> on 2025-04-13 00:00:00+00:00
[2025-04-14T05:19:30.733+0000] {warnings.py:112} WARNING - /home/***/.local/lib/python3.12/site-packages/***/task/task_runner/standard_task_runner.py:70: DeprecationWarning: This process (pid=165) is multi-threaded, use of fork() may lead to deadlocks in the child.
  pid = os.fork()

[2025-04-14T05:19:30.734+0000] {standard_task_runner.py:72} INFO - Started process 167 to run task
[2025-04-14T05:19:30.736+0000] {standard_task_runner.py:104} INFO - Running: ['***', 'tasks', 'run', 'data_ingestion_gcs_dag', 'fetch_permits_task', 'scheduled__2025-04-13T00:00:00+00:00', '--job-id', '5', '--raw', '--subdir', 'DAGS_FOLDER/data_ingestion_gcs_dag.py', '--cfg-path', '/tmp/tmprunlokr_']
[2025-04-14T05:19:30.737+0000] {standard_task_runner.py:105} INFO - Job 5: Subtask fetch_permits_task
[2025-04-14T05:19:30.767+0000] {task_command.py:467} INFO - Running <TaskInstance: data_ingestion_gcs_dag.fetch_permits_task scheduled__2025-04-13T00:00:00+00:00 [running]> on host 958b532773e9
[2025-04-14T05:19:30.806+0000] {taskinstance.py:3134} INFO - Exporting env vars: AIRFLOW_CTX_DAG_OWNER='***' AIRFLOW_CTX_DAG_ID='data_ingestion_gcs_dag' AIRFLOW_CTX_TASK_ID='fetch_permits_task' AIRFLOW_CTX_EXECUTION_DATE='2025-04-13T00:00:00+00:00' AIRFLOW_CTX_TRY_NUMBER='2' AIRFLOW_CTX_DAG_RUN_ID='scheduled__2025-04-13T00:00:00+00:00'
[2025-04-14T05:19:30.807+0000] {logging_mixin.py:190} INFO - Task instance is in running state
[2025-04-14T05:19:30.807+0000] {logging_mixin.py:190} INFO -  Previous state of the Task instance: queued
[2025-04-14T05:19:30.808+0000] {logging_mixin.py:190} INFO - Current task name:fetch_permits_task state:running start_date:2025-04-14 05:19:30.718996+00:00
[2025-04-14T05:19:30.808+0000] {logging_mixin.py:190} INFO - Dag name:data_ingestion_gcs_dag and current dag run status:running
[2025-04-14T05:19:30.808+0000] {taskinstance.py:732} INFO - ::endgroup::
[2025-04-14T05:19:30.808+0000] {baseoperator.py:423} WARNING - BranchPythonOperator.execute cannot be called outside TaskInstance!
[2025-04-14T05:19:30.815+0000] {logging_mixin.py:190} INFO - Fetching records for 2020-04-29 (offset=0)
[2025-04-14T05:19:31.475+0000] {taskinstance.py:3313} ERROR - Task failed with exception
Traceback (most recent call last):
  File "/home/airflow/.local/lib/python3.12/site-packages/airflow/models/taskinstance.py", line 768, in _execute_task
    result = _execute_callable(context=context, **execute_callable_kwargs)
             ^^^^^^^^^^^^^^^^^^^^^^^^^^^^^^^^^^^^^^^^^^^^^^^^^^^^^^^^^^^^^
  File "/home/airflow/.local/lib/python3.12/site-packages/airflow/models/taskinstance.py", line 734, in _execute_callable
    return ExecutionCallableRunner(
           ^^^^^^^^^^^^^^^^^^^^^^^^
  File "/home/airflow/.local/lib/python3.12/site-packages/airflow/utils/operator_helpers.py", line 252, in run
    return self.func(*args, **kwargs)
           ^^^^^^^^^^^^^^^^^^^^^^^^^^
  File "/home/airflow/.local/lib/python3.12/site-packages/airflow/models/baseoperator.py", line 424, in wrapper
    return func(self, *args, **kwargs)
           ^^^^^^^^^^^^^^^^^^^^^^^^^^^
  File "/home/airflow/.local/lib/python3.12/site-packages/airflow/operators/python.py", line 274, in execute
    return self.do_branch(context, super().execute(context))
                                   ^^^^^^^^^^^^^^^^^^^^^^^^
  File "/home/airflow/.local/lib/python3.12/site-packages/airflow/models/baseoperator.py", line 424, in wrapper
    return func(self, *args, **kwargs)
           ^^^^^^^^^^^^^^^^^^^^^^^^^^^
  File "/home/airflow/.local/lib/python3.12/site-packages/airflow/operators/python.py", line 238, in execute
    return_value = self.execute_callable()
                   ^^^^^^^^^^^^^^^^^^^^^^^
  File "/home/airflow/.local/lib/python3.12/site-packages/airflow/operators/python.py", line 256, in execute_callable
    return runner.run(*self.op_args, **self.op_kwargs)
           ^^^^^^^^^^^^^^^^^^^^^^^^^^^^^^^^^^^^^^^^^^^
  File "/home/airflow/.local/lib/python3.12/site-packages/airflow/utils/operator_helpers.py", line 252, in run
    return self.func(*args, **kwargs)
           ^^^^^^^^^^^^^^^^^^^^^^^^^^
  File "/opt/airflow/dags/data_ingestion_gcs_dag.py", line 86, in fetch_permits
    results = client.get(
              ^^^^^^^^^^^
  File "/home/airflow/.local/lib/python3.12/site-packages/sodapy/socrata.py", line 412, in get
    response = self._perform_request(
               ^^^^^^^^^^^^^^^^^^^^^^
  File "/home/airflow/.local/lib/python3.12/site-packages/sodapy/socrata.py", line 555, in _perform_request
    utils.raise_for_status(response)
  File "/home/airflow/.local/lib/python3.12/site-packages/sodapy/utils.py", line 30, in raise_for_status
    raise requests.exceptions.HTTPError(http_error_msg, response=response)
requests.exceptions.HTTPError: 400 Client Error: Bad Request.
	Unrecognized arguments [timeout]
[2025-04-14T05:19:31.497+0000] {logging_mixin.py:190} INFO - Task instance in failure state
[2025-04-14T05:19:31.498+0000] {logging_mixin.py:190} INFO - Task start:2025-04-14 05:19:30.718996+00:00 end:2025-04-14 05:19:31.496601+00:00 duration:0.777605
[2025-04-14T05:19:31.499+0000] {logging_mixin.py:190} INFO - Task:<Task(BranchPythonOperator): fetch_permits_task> dag:<DAG: data_ingestion_gcs_dag> dagrun:<DagRun data_ingestion_gcs_dag @ 2025-04-13 00:00:00+00:00: scheduled__2025-04-13T00:00:00+00:00, state:running, queued_at: 2025-04-14 05:14:22.988895+00:00. externally triggered: False>
[2025-04-14T05:19:31.500+0000] {logging_mixin.py:190} INFO - Failure caused by 400 Client Error: Bad Request.
	Unrecognized arguments [timeout]
[2025-04-14T05:19:31.501+0000] {taskinstance.py:1226} INFO - Marking task as FAILED. dag_id=data_ingestion_gcs_dag, task_id=fetch_permits_task, run_id=scheduled__2025-04-13T00:00:00+00:00, execution_date=20250413T000000, start_date=20250414T051930, end_date=20250414T051931
[2025-04-14T05:19:31.550+0000] {taskinstance.py:341} INFO - ::group::Post task execution logs
[2025-04-14T05:19:31.551+0000] {standard_task_runner.py:124} ERROR - Failed to execute job 5 for task fetch_permits_task (400 Client Error: Bad Request.
	Unrecognized arguments [timeout]; 167)
Traceback (most recent call last):
  File "/home/airflow/.local/lib/python3.12/site-packages/airflow/task/task_runner/standard_task_runner.py", line 117, in _start_by_fork
    ret = args.func(args, dag=self.dag)
          ^^^^^^^^^^^^^^^^^^^^^^^^^^^^^
  File "/home/airflow/.local/lib/python3.12/site-packages/airflow/cli/cli_config.py", line 49, in command
    return func(*args, **kwargs)
           ^^^^^^^^^^^^^^^^^^^^^
  File "/home/airflow/.local/lib/python3.12/site-packages/airflow/utils/cli.py", line 116, in wrapper
    return f(*args, **kwargs)
           ^^^^^^^^^^^^^^^^^^
  File "/home/airflow/.local/lib/python3.12/site-packages/airflow/cli/commands/task_command.py", line 483, in task_run
    task_return_code = _run_task_by_selected_method(args, _dag, ti)
                       ^^^^^^^^^^^^^^^^^^^^^^^^^^^^^^^^^^^^^^^^^^^^
  File "/home/airflow/.local/lib/python3.12/site-packages/airflow/cli/commands/task_command.py", line 256, in _run_task_by_selected_method
    return _run_raw_task(args, ti)
           ^^^^^^^^^^^^^^^^^^^^^^^
  File "/home/airflow/.local/lib/python3.12/site-packages/airflow/cli/commands/task_command.py", line 341, in _run_raw_task
    return ti._run_raw_task(
           ^^^^^^^^^^^^^^^^^
  File "/home/airflow/.local/lib/python3.12/site-packages/airflow/utils/session.py", line 97, in wrapper
    return func(*args, session=session, **kwargs)
           ^^^^^^^^^^^^^^^^^^^^^^^^^^^^^^^^^^^^^^
  File "/home/airflow/.local/lib/python3.12/site-packages/airflow/models/taskinstance.py", line 3006, in _run_raw_task
    return _run_raw_task(
           ^^^^^^^^^^^^^^
  File "/home/airflow/.local/lib/python3.12/site-packages/airflow/models/taskinstance.py", line 274, in _run_raw_task
    TaskInstance._execute_task_with_callbacks(
  File "/home/airflow/.local/lib/python3.12/site-packages/airflow/models/taskinstance.py", line 3161, in _execute_task_with_callbacks
    result = self._execute_task(context, task_orig)
             ^^^^^^^^^^^^^^^^^^^^^^^^^^^^^^^^^^^^^^
  File "/home/airflow/.local/lib/python3.12/site-packages/airflow/models/taskinstance.py", line 3185, in _execute_task
    return _execute_task(self, context, task_orig)
           ^^^^^^^^^^^^^^^^^^^^^^^^^^^^^^^^^^^^^^^
  File "/home/airflow/.local/lib/python3.12/site-packages/airflow/models/taskinstance.py", line 768, in _execute_task
    result = _execute_callable(context=context, **execute_callable_kwargs)
             ^^^^^^^^^^^^^^^^^^^^^^^^^^^^^^^^^^^^^^^^^^^^^^^^^^^^^^^^^^^^^
  File "/home/airflow/.local/lib/python3.12/site-packages/airflow/models/taskinstance.py", line 734, in _execute_callable
    return ExecutionCallableRunner(
           ^^^^^^^^^^^^^^^^^^^^^^^^
  File "/home/airflow/.local/lib/python3.12/site-packages/airflow/utils/operator_helpers.py", line 252, in run
    return self.func(*args, **kwargs)
           ^^^^^^^^^^^^^^^^^^^^^^^^^^
  File "/home/airflow/.local/lib/python3.12/site-packages/airflow/models/baseoperator.py", line 424, in wrapper
    return func(self, *args, **kwargs)
           ^^^^^^^^^^^^^^^^^^^^^^^^^^^
  File "/home/airflow/.local/lib/python3.12/site-packages/airflow/operators/python.py", line 274, in execute
    return self.do_branch(context, super().execute(context))
                                   ^^^^^^^^^^^^^^^^^^^^^^^^
  File "/home/airflow/.local/lib/python3.12/site-packages/airflow/models/baseoperator.py", line 424, in wrapper
    return func(self, *args, **kwargs)
           ^^^^^^^^^^^^^^^^^^^^^^^^^^^
  File "/home/airflow/.local/lib/python3.12/site-packages/airflow/operators/python.py", line 238, in execute
    return_value = self.execute_callable()
                   ^^^^^^^^^^^^^^^^^^^^^^^
  File "/home/airflow/.local/lib/python3.12/site-packages/airflow/operators/python.py", line 256, in execute_callable
    return runner.run(*self.op_args, **self.op_kwargs)
           ^^^^^^^^^^^^^^^^^^^^^^^^^^^^^^^^^^^^^^^^^^^
  File "/home/airflow/.local/lib/python3.12/site-packages/airflow/utils/operator_helpers.py", line 252, in run
    return self.func(*args, **kwargs)
           ^^^^^^^^^^^^^^^^^^^^^^^^^^
  File "/opt/airflow/dags/data_ingestion_gcs_dag.py", line 86, in fetch_permits
    results = client.get(
              ^^^^^^^^^^^
  File "/home/airflow/.local/lib/python3.12/site-packages/sodapy/socrata.py", line 412, in get
    response = self._perform_request(
               ^^^^^^^^^^^^^^^^^^^^^^
  File "/home/airflow/.local/lib/python3.12/site-packages/sodapy/socrata.py", line 555, in _perform_request
    utils.raise_for_status(response)
  File "/home/airflow/.local/lib/python3.12/site-packages/sodapy/utils.py", line 30, in raise_for_status
    raise requests.exceptions.HTTPError(http_error_msg, response=response)
requests.exceptions.HTTPError: 400 Client Error: Bad Request.
	Unrecognized arguments [timeout]
[2025-04-14T05:19:31.572+0000] {local_task_job_runner.py:266} INFO - Task exited with return code 1
[2025-04-14T05:19:31.597+0000] {taskinstance.py:3901} INFO - 0 downstream tasks scheduled from follow-on schedule check
[2025-04-14T05:19:31.602+0000] {local_task_job_runner.py:245} INFO - ::endgroup::
