[2025-04-13T03:19:52.207+0000] {local_task_job_runner.py:123} INFO - ::group::Pre task execution logs
[2025-04-13T03:19:52.216+0000] {taskinstance.py:2614} INFO - Dependencies all met for dep_context=non-requeueable deps ti=<TaskInstance: data_ingestion_gcs_dag.get_last_issuance_date_task manual__2025-04-13T03:19:34.436899+00:00 [queued]>
[2025-04-13T03:19:52.221+0000] {taskinstance.py:2614} INFO - Dependencies all met for dep_context=requeueable deps ti=<TaskInstance: data_ingestion_gcs_dag.get_last_issuance_date_task manual__2025-04-13T03:19:34.436899+00:00 [queued]>
[2025-04-13T03:19:52.221+0000] {taskinstance.py:2867} INFO - Starting attempt 1 of 2
[2025-04-13T03:19:52.229+0000] {taskinstance.py:2890} INFO - Executing <Task(PythonOperator): get_last_issuance_date_task> on 2025-04-13 03:19:34.436899+00:00
[2025-04-13T03:19:52.233+0000] {warnings.py:112} WARNING - /home/***/.local/lib/python3.12/site-packages/***/task/task_runner/standard_task_runner.py:70: DeprecationWarning: This process (pid=109) is multi-threaded, use of fork() may lead to deadlocks in the child.
  pid = os.fork()

[2025-04-13T03:19:52.234+0000] {standard_task_runner.py:72} INFO - Started process 111 to run task
[2025-04-13T03:19:52.234+0000] {standard_task_runner.py:104} INFO - Running: ['***', 'tasks', 'run', 'data_ingestion_gcs_dag', 'get_last_issuance_date_task', 'manual__2025-04-13T03:19:34.436899+00:00', '--job-id', '7', '--raw', '--subdir', 'DAGS_FOLDER/data_ingestion_gcs_dag.py', '--cfg-path', '/tmp/tmpvf9l329i']
[2025-04-13T03:19:52.235+0000] {standard_task_runner.py:105} INFO - Job 7: Subtask get_last_issuance_date_task
[2025-04-13T03:19:52.268+0000] {task_command.py:467} INFO - Running <TaskInstance: data_ingestion_gcs_dag.get_last_issuance_date_task manual__2025-04-13T03:19:34.436899+00:00 [running]> on host 1b4e74840e23
[2025-04-13T03:19:52.308+0000] {taskinstance.py:3134} INFO - Exporting env vars: AIRFLOW_CTX_DAG_OWNER='***' AIRFLOW_CTX_DAG_ID='data_ingestion_gcs_dag' AIRFLOW_CTX_TASK_ID='get_last_issuance_date_task' AIRFLOW_CTX_EXECUTION_DATE='2025-04-13T03:19:34.436899+00:00' AIRFLOW_CTX_TRY_NUMBER='1' AIRFLOW_CTX_DAG_RUN_ID='manual__2025-04-13T03:19:34.436899+00:00'
[2025-04-13T03:19:52.309+0000] {logging_mixin.py:190} INFO - Task instance is in running state
[2025-04-13T03:19:52.310+0000] {logging_mixin.py:190} INFO -  Previous state of the Task instance: queued
[2025-04-13T03:19:52.310+0000] {logging_mixin.py:190} INFO - Current task name:get_last_issuance_date_task state:running start_date:2025-04-13 03:19:52.216440+00:00
[2025-04-13T03:19:52.310+0000] {logging_mixin.py:190} INFO - Dag name:data_ingestion_gcs_dag and current dag run status:running
[2025-04-13T03:19:52.310+0000] {taskinstance.py:732} INFO - ::endgroup::
[2025-04-13T03:19:53.163+0000] {taskinstance.py:3313} ERROR - Task failed with exception
Traceback (most recent call last):
  File "/home/airflow/.local/lib/python3.12/site-packages/airflow/models/taskinstance.py", line 768, in _execute_task
    result = _execute_callable(context=context, **execute_callable_kwargs)
             ^^^^^^^^^^^^^^^^^^^^^^^^^^^^^^^^^^^^^^^^^^^^^^^^^^^^^^^^^^^^^
  File "/home/airflow/.local/lib/python3.12/site-packages/airflow/models/taskinstance.py", line 734, in _execute_callable
    return ExecutionCallableRunner(
           ^^^^^^^^^^^^^^^^^^^^^^^^
  File "/home/airflow/.local/lib/python3.12/site-packages/airflow/utils/operator_helpers.py", line 252, in run
    return self.func(*args, **kwargs)
           ^^^^^^^^^^^^^^^^^^^^^^^^^^
  File "/home/airflow/.local/lib/python3.12/site-packages/airflow/models/baseoperator.py", line 424, in wrapper
    return func(self, *args, **kwargs)
           ^^^^^^^^^^^^^^^^^^^^^^^^^^^
  File "/home/airflow/.local/lib/python3.12/site-packages/airflow/operators/python.py", line 238, in execute
    return_value = self.execute_callable()
                   ^^^^^^^^^^^^^^^^^^^^^^^
  File "/home/airflow/.local/lib/python3.12/site-packages/airflow/operators/python.py", line 256, in execute_callable
    return runner.run(*self.op_args, **self.op_kwargs)
           ^^^^^^^^^^^^^^^^^^^^^^^^^^^^^^^^^^^^^^^^^^^
  File "/home/airflow/.local/lib/python3.12/site-packages/airflow/utils/operator_helpers.py", line 252, in run
    return self.func(*args, **kwargs)
           ^^^^^^^^^^^^^^^^^^^^^^^^^^
  File "/opt/airflow/dags/data_ingestion_gcs_dag.py", line 41, in get_last_issuance_date
    rows = query_job.result()  # Waits for query to finish
           ^^^^^^^^^^^^^^^^^^
  File "/home/airflow/.local/lib/python3.12/site-packages/google/cloud/bigquery/job/query.py", line 1590, in result
    do_get_result()
  File "/home/airflow/.local/lib/python3.12/site-packages/google/api_core/retry/retry_unary.py", line 293, in retry_wrapped_func
    return retry_target(
           ^^^^^^^^^^^^^
  File "/home/airflow/.local/lib/python3.12/site-packages/google/api_core/retry/retry_unary.py", line 153, in retry_target
    _retry_error_helper(
  File "/home/airflow/.local/lib/python3.12/site-packages/google/api_core/retry/retry_base.py", line 212, in _retry_error_helper
    raise final_exc from source_exc
  File "/home/airflow/.local/lib/python3.12/site-packages/google/api_core/retry/retry_unary.py", line 144, in retry_target
    result = target()
             ^^^^^^^^
  File "/home/airflow/.local/lib/python3.12/site-packages/google/cloud/bigquery/job/query.py", line 1579, in do_get_result
    super(QueryJob, self).result(retry=retry, timeout=timeout)
  File "/home/airflow/.local/lib/python3.12/site-packages/google/cloud/bigquery/job/base.py", line 971, in result
    return super(_AsyncJob, self).result(timeout=timeout, **kwargs)
           ^^^^^^^^^^^^^^^^^^^^^^^^^^^^^^^^^^^^^^^^^^^^^^^^^^^^^^^^
  File "/home/airflow/.local/lib/python3.12/site-packages/google/api_core/future/polling.py", line 261, in result
    raise self._exception
google.api_core.exceptions.BadRequest: 400 Unrecognized name: issuance_date at [2:20]; reason: invalidQuery, location: query, message: Unrecognized name: issuance_date at [2:20]

Location: US
Job ID: b4df1f80-777b-4258-9069-ea3f6e760c98

[2025-04-13T03:19:53.184+0000] {logging_mixin.py:190} INFO - Task instance in failure state
[2025-04-13T03:19:53.185+0000] {logging_mixin.py:190} INFO - Task start:2025-04-13 03:19:52.216440+00:00 end:2025-04-13 03:19:53.183894+00:00 duration:0.967454
[2025-04-13T03:19:53.185+0000] {logging_mixin.py:190} INFO - Task:<Task(PythonOperator): get_last_issuance_date_task> dag:<DAG: data_ingestion_gcs_dag> dagrun:<DagRun data_ingestion_gcs_dag @ 2025-04-13 03:19:34.436899+00:00: manual__2025-04-13T03:19:34.436899+00:00, state:running, queued_at: 2025-04-13 03:19:34.448802+00:00. externally triggered: True>
[2025-04-13T03:19:53.186+0000] {logging_mixin.py:190} INFO - Failure caused by 400 Unrecognized name: issuance_date at [2:20]; reason: invalidQuery, location: query, message: Unrecognized name: issuance_date at [2:20]

Location: US
Job ID: b4df1f80-777b-4258-9069-ea3f6e760c98
[2025-04-13T03:19:53.186+0000] {taskinstance.py:1226} INFO - Marking task as UP_FOR_RETRY. dag_id=data_ingestion_gcs_dag, task_id=get_last_issuance_date_task, run_id=manual__2025-04-13T03:19:34.436899+00:00, execution_date=20250413T031934, start_date=20250413T031952, end_date=20250413T031953
[2025-04-13T03:19:53.205+0000] {taskinstance.py:341} INFO - ::group::Post task execution logs
[2025-04-13T03:19:53.205+0000] {standard_task_runner.py:124} ERROR - Failed to execute job 7 for task get_last_issuance_date_task (400 Unrecognized name: issuance_date at [2:20]; reason: invalidQuery, location: query, message: Unrecognized name: issuance_date at [2:20]

Location: US
Job ID: b4df1f80-777b-4258-9069-ea3f6e760c98
; 111)
Traceback (most recent call last):
  File "/home/airflow/.local/lib/python3.12/site-packages/airflow/task/task_runner/standard_task_runner.py", line 117, in _start_by_fork
    ret = args.func(args, dag=self.dag)
          ^^^^^^^^^^^^^^^^^^^^^^^^^^^^^
  File "/home/airflow/.local/lib/python3.12/site-packages/airflow/cli/cli_config.py", line 49, in command
    return func(*args, **kwargs)
           ^^^^^^^^^^^^^^^^^^^^^
  File "/home/airflow/.local/lib/python3.12/site-packages/airflow/utils/cli.py", line 116, in wrapper
    return f(*args, **kwargs)
           ^^^^^^^^^^^^^^^^^^
  File "/home/airflow/.local/lib/python3.12/site-packages/airflow/cli/commands/task_command.py", line 483, in task_run
    task_return_code = _run_task_by_selected_method(args, _dag, ti)
                       ^^^^^^^^^^^^^^^^^^^^^^^^^^^^^^^^^^^^^^^^^^^^
  File "/home/airflow/.local/lib/python3.12/site-packages/airflow/cli/commands/task_command.py", line 256, in _run_task_by_selected_method
    return _run_raw_task(args, ti)
           ^^^^^^^^^^^^^^^^^^^^^^^
  File "/home/airflow/.local/lib/python3.12/site-packages/airflow/cli/commands/task_command.py", line 341, in _run_raw_task
    return ti._run_raw_task(
           ^^^^^^^^^^^^^^^^^
  File "/home/airflow/.local/lib/python3.12/site-packages/airflow/utils/session.py", line 97, in wrapper
    return func(*args, session=session, **kwargs)
           ^^^^^^^^^^^^^^^^^^^^^^^^^^^^^^^^^^^^^^
  File "/home/airflow/.local/lib/python3.12/site-packages/airflow/models/taskinstance.py", line 3006, in _run_raw_task
    return _run_raw_task(
           ^^^^^^^^^^^^^^
  File "/home/airflow/.local/lib/python3.12/site-packages/airflow/models/taskinstance.py", line 274, in _run_raw_task
    TaskInstance._execute_task_with_callbacks(
  File "/home/airflow/.local/lib/python3.12/site-packages/airflow/models/taskinstance.py", line 3161, in _execute_task_with_callbacks
    result = self._execute_task(context, task_orig)
             ^^^^^^^^^^^^^^^^^^^^^^^^^^^^^^^^^^^^^^
  File "/home/airflow/.local/lib/python3.12/site-packages/airflow/models/taskinstance.py", line 3185, in _execute_task
    return _execute_task(self, context, task_orig)
           ^^^^^^^^^^^^^^^^^^^^^^^^^^^^^^^^^^^^^^^
  File "/home/airflow/.local/lib/python3.12/site-packages/airflow/models/taskinstance.py", line 768, in _execute_task
    result = _execute_callable(context=context, **execute_callable_kwargs)
             ^^^^^^^^^^^^^^^^^^^^^^^^^^^^^^^^^^^^^^^^^^^^^^^^^^^^^^^^^^^^^
  File "/home/airflow/.local/lib/python3.12/site-packages/airflow/models/taskinstance.py", line 734, in _execute_callable
    return ExecutionCallableRunner(
           ^^^^^^^^^^^^^^^^^^^^^^^^
  File "/home/airflow/.local/lib/python3.12/site-packages/airflow/utils/operator_helpers.py", line 252, in run
    return self.func(*args, **kwargs)
           ^^^^^^^^^^^^^^^^^^^^^^^^^^
  File "/home/airflow/.local/lib/python3.12/site-packages/airflow/models/baseoperator.py", line 424, in wrapper
    return func(self, *args, **kwargs)
           ^^^^^^^^^^^^^^^^^^^^^^^^^^^
  File "/home/airflow/.local/lib/python3.12/site-packages/airflow/operators/python.py", line 238, in execute
    return_value = self.execute_callable()
                   ^^^^^^^^^^^^^^^^^^^^^^^
  File "/home/airflow/.local/lib/python3.12/site-packages/airflow/operators/python.py", line 256, in execute_callable
    return runner.run(*self.op_args, **self.op_kwargs)
           ^^^^^^^^^^^^^^^^^^^^^^^^^^^^^^^^^^^^^^^^^^^
  File "/home/airflow/.local/lib/python3.12/site-packages/airflow/utils/operator_helpers.py", line 252, in run
    return self.func(*args, **kwargs)
           ^^^^^^^^^^^^^^^^^^^^^^^^^^
  File "/opt/airflow/dags/data_ingestion_gcs_dag.py", line 41, in get_last_issuance_date
    rows = query_job.result()  # Waits for query to finish
           ^^^^^^^^^^^^^^^^^^
  File "/home/airflow/.local/lib/python3.12/site-packages/google/cloud/bigquery/job/query.py", line 1590, in result
    do_get_result()
  File "/home/airflow/.local/lib/python3.12/site-packages/google/api_core/retry/retry_unary.py", line 293, in retry_wrapped_func
    return retry_target(
           ^^^^^^^^^^^^^
  File "/home/airflow/.local/lib/python3.12/site-packages/google/api_core/retry/retry_unary.py", line 153, in retry_target
    _retry_error_helper(
  File "/home/airflow/.local/lib/python3.12/site-packages/google/api_core/retry/retry_base.py", line 212, in _retry_error_helper
    raise final_exc from source_exc
  File "/home/airflow/.local/lib/python3.12/site-packages/google/api_core/retry/retry_unary.py", line 144, in retry_target
    result = target()
             ^^^^^^^^
  File "/home/airflow/.local/lib/python3.12/site-packages/google/cloud/bigquery/job/query.py", line 1579, in do_get_result
    super(QueryJob, self).result(retry=retry, timeout=timeout)
  File "/home/airflow/.local/lib/python3.12/site-packages/google/cloud/bigquery/job/base.py", line 971, in result
    return super(_AsyncJob, self).result(timeout=timeout, **kwargs)
           ^^^^^^^^^^^^^^^^^^^^^^^^^^^^^^^^^^^^^^^^^^^^^^^^^^^^^^^^
  File "/home/airflow/.local/lib/python3.12/site-packages/google/api_core/future/polling.py", line 261, in result
    raise self._exception
google.api_core.exceptions.BadRequest: 400 Unrecognized name: issuance_date at [2:20]; reason: invalidQuery, location: query, message: Unrecognized name: issuance_date at [2:20]

Location: US
Job ID: b4df1f80-777b-4258-9069-ea3f6e760c98

[2025-04-13T03:19:53.234+0000] {local_task_job_runner.py:266} INFO - Task exited with return code 1
[2025-04-13T03:19:53.263+0000] {taskinstance.py:3901} INFO - 0 downstream tasks scheduled from follow-on schedule check
[2025-04-13T03:19:53.264+0000] {local_task_job_runner.py:245} INFO - ::endgroup::
